{
 "cells": [
  {
   "cell_type": "code",
   "execution_count": 2,
   "metadata": {},
   "outputs": [
    {
     "name": "stdout",
     "output_type": "stream",
     "text": [
      "Collecting azure-datalake-store\n",
      "  Using cached azure_datalake_store-0.0.48-py2.py3-none-any.whl (53 kB)\n",
      "Collecting adal>=0.4.2\n",
      "  Using cached adal-1.2.2-py2.py3-none-any.whl (53 kB)\n",
      "Requirement already satisfied: cffi in /opt/conda/lib/python3.7/site-packages (from azure-datalake-store) (1.14.0)\n",
      "Requirement already satisfied: requests>=2.20.0 in /opt/conda/lib/python3.7/site-packages (from azure-datalake-store) (2.23.0)\n",
      "Requirement already satisfied: PyJWT>=1.0.0 in /opt/conda/lib/python3.7/site-packages (from adal>=0.4.2->azure-datalake-store) (1.7.1)\n",
      "Requirement already satisfied: cryptography>=1.1.0 in /opt/conda/lib/python3.7/site-packages (from adal>=0.4.2->azure-datalake-store) (2.8)\n",
      "Requirement already satisfied: python-dateutil>=2.1.0 in /opt/conda/lib/python3.7/site-packages (from adal>=0.4.2->azure-datalake-store) (2.8.1)\n",
      "Requirement already satisfied: pycparser in /opt/conda/lib/python3.7/site-packages (from cffi->azure-datalake-store) (2.20)\n",
      "Requirement already satisfied: urllib3!=1.25.0,!=1.25.1,<1.26,>=1.21.1 in /opt/conda/lib/python3.7/site-packages (from requests>=2.20.0->azure-datalake-store) (1.25.7)\n",
      "Requirement already satisfied: certifi>=2017.4.17 in /opt/conda/lib/python3.7/site-packages (from requests>=2.20.0->azure-datalake-store) (2019.11.28)\n",
      "Requirement already satisfied: idna<3,>=2.5 in /opt/conda/lib/python3.7/site-packages (from requests>=2.20.0->azure-datalake-store) (2.9)\n",
      "Requirement already satisfied: chardet<4,>=3.0.2 in /opt/conda/lib/python3.7/site-packages (from requests>=2.20.0->azure-datalake-store) (3.0.4)\n",
      "Requirement already satisfied: six>=1.4.1 in /opt/conda/lib/python3.7/site-packages (from cryptography>=1.1.0->adal>=0.4.2->azure-datalake-store) (1.14.0)\n",
      "Installing collected packages: adal, azure-datalake-store\n",
      "Successfully installed adal-1.2.2 azure-datalake-store-0.0.48\n"
     ]
    }
   ],
   "source": [
    "!pip install azure-datalake-store "
   ]
  },
  {
   "cell_type": "code",
   "execution_count": 1,
   "metadata": {},
   "outputs": [],
   "source": [
    "from azure.datalake.store import core, lib, multithread\n"
   ]
  },
  {
   "cell_type": "code",
   "execution_count": 2,
   "metadata": {},
   "outputs": [],
   "source": [
    "from pyspark.sql import SparkSession\n"
   ]
  },
  {
   "cell_type": "code",
   "execution_count": 3,
   "metadata": {},
   "outputs": [],
   "source": [
    "spark = SparkSession.builder \\\n",
    "            .master(\"local[8]\") \\\n",
    "            .appName(\"airflow_app\") \\\n",
    "            .config('spark.executor.memory', '16g') \\\n",
    "            .config('spark.driver.memory', '16g') \\\n",
    "            .config('spark.sql.execution.pandas.respectSessionTimeZone', False) \\\n",
    "            .config(\"spark.driver.maxResultSize\", \"2048MB\") \\\n",
    "            .config(\"spark.port.maxRetries\", \"100\") \\\n",
    "            .config(\"spark.sql.execution.arrow.enabled\", \"true\") \\\n",
    "            .getOrCreate()\n"
   ]
  },
  {
   "cell_type": "code",
   "execution_count": 4,
   "metadata": {},
   "outputs": [
    {
     "name": "stdout",
     "output_type": "stream",
     "text": [
      "To sign in, use a web browser to open the page https://microsoft.com/devicelogin and enter the code B3B4PQPLF to authenticate.\n"
     ]
    }
   ],
   "source": [
    "adlCreds = lib.auth(url_suffix='raizenprd01', resource='https://datalake.azure.net/')"
   ]
  },
  {
   "cell_type": "code",
   "execution_count": 5,
   "metadata": {},
   "outputs": [],
   "source": [
    "spark.conf.set(\"fs.adl.oauth2.access.token.provider.type\", \"RefreshToken\")\n",
    "spark.conf.set(\"fs.adl.oauth2.client.id\", adlCreds.token['client'])\n",
    "spark.conf.set(\"fs.adl.oauth2.refresh.token\", adlCreds.token['refreshToken'])\n"
   ]
  },
  {
   "cell_type": "code",
   "execution_count": 6,
   "metadata": {},
   "outputs": [],
   "source": [
    "import pandas as pd\n",
    "from pyspark.sql.functions import *\n",
    "from pyspark.sql import functions as F\n",
    "from pyspark.sql.types import StringType,StructField, StructType  "
   ]
  },
  {
   "cell_type": "code",
   "execution_count": 7,
   "metadata": {},
   "outputs": [],
   "source": [
    "df_vendas_dia = spark.read.parquet('adl://raizenprd01.azuredatalakestore.net/ldt_dev/sandbox/previsao_demanda/03_primary/vendas_dia').where((F.col('Date') < F.lit('2019-08-01'))&(F.col('Date') > F.lit('2019-07-01')))"
   ]
  },
  {
   "cell_type": "code",
   "execution_count": 14,
   "metadata": {},
   "outputs": [],
   "source": [
    "schema_mes = StructType([\n",
    "        StructField('_c0', StringType(), True),\n",
    "        StructField('Empr', StringType(), True),\n",
    "        StructField('Cent', StringType(), True),\n",
    "        StructField('Nota Fiscal', StringType(), True),\n",
    "        StructField('Data Saida', StringType(), True),\n",
    "        StructField('Data Criacao', StringType(), True),\n",
    "        StructField('UF', StringType(), True),\n",
    "        StructField('Faturamento', StringType(), True),\n",
    "        StructField('Itm', StringType(), True),\n",
    "        StructField('Vencimento', StringType(), True),\n",
    "        StructField('TpOV', StringType(), True),\n",
    "        StructField('Ordem Vendas', StringType(), True),\n",
    "        StructField('IBM', StringType(), True),\n",
    "        StructField('Razao Social', StringType(), True),\n",
    "        StructField('Canal', StringType(), True),\n",
    "        StructField('Material', StringType(), True),\n",
    "        StructField('Descricao', StringType(), True),\n",
    "        StructField(' Quantidade', StringType(), True),\n",
    "        StructField('UM', StringType(), True),\n",
    "        StructField('Cond.Pgto', StringType(), True),\n",
    "        StructField('Inco', StringType(), True),\n",
    "        StructField('C.Exp', StringType(), True),\n",
    "        StructField('Valor item', StringType(), True),\n",
    "        StructField('Valor ZPFL', StringType(), True),\n",
    "        StructField('Valor ZPFN', StringType(), True),\n",
    "        StructField('Valor ZENC', StringType(), True),\n",
    "        StructField('Imposto', StringType(), True),\n",
    "        StructField('Valor ZDB1', StringType(), True),\n",
    "        StructField('Target Block', StringType(), True),\n",
    "        StructField('UN', StringType(), True),\n",
    "        StructField('Valor ZDDB', StringType(), True),\n",
    "        StructField('Valor ZDIA', StringType(), True),\n",
    "        StructField('Valor ZDFR', StringType(), True),\n",
    "        StructField('Valor ICM3', StringType(), True),\n",
    "        StructField('Valor ICS3', StringType(), True),\n",
    "        StructField('Rep.Vendas', StringType(), True),\n",
    "        StructField('Acesso ZPFL', StringType(), True),\n",
    "        StructField('Volume', StringType(), True),\n",
    "        StructField('UN_', StringType(), True),\n",
    "        StructField('Hora Fat', StringType(), True),\n",
    "        StructField('ReferÃªncia', StringType(), True),\n",
    "    ])"
   ]
  },
  {
   "cell_type": "code",
   "execution_count": 15,
   "metadata": {},
   "outputs": [],
   "source": [
    "df_mes = spark.read.format('csv')\\\n",
    "        .option('sep','|').schema(schema_mes)\\\n",
    "        .load('adl://raizenprd01.azuredatalakestore.net/ldt_dev/sandbox/previsao_demanda/01_raw/vendas_dia_complemento/mes')\\\n",
    "        .where(\"Empr is not null and Empr <> 'Empr' \").select('Data Saida','Cent','Material','IBM','Volume','Canal')"
   ]
  },
  {
   "cell_type": "code",
   "execution_count": 16,
   "metadata": {},
   "outputs": [],
   "source": [
    "df_mes = df_mes\\\n",
    "    .withColumn(\"Date\", F.to_date(F.col(\"Data Saida\"), \"dd.MM.yyyy\"))\\\n",
    "    .withColumn(\"Volume\",F.regexp_replace(F.regexp_replace(df_mes.Volume,\"\\.\",\"\"),\",\",\".\").cast(\"double\"))\\\n",
    "    .withColumnRenamed('Canal','Segmento').withColumnRenamed('Cent','Base')\\\n",
    "    .withColumnRenamed('Material','SKU')\\\n",
    "    .where(F.col('Date') < F.lit('2019-10-01'))\\\n",
    "    .select('Date','Base','SKU','IBM','Volume','Segmento')"
   ]
  },
  {
   "cell_type": "code",
   "execution_count": 17,
   "metadata": {},
   "outputs": [],
   "source": [
    "df_mes = df_mes.groupBy(\"Date\",\"Base\",\"SKU\",\"IBM\",\"Segmento\").agg({\"Volume\": \"sum\"})"
   ]
  },
  {
   "cell_type": "code",
   "execution_count": 18,
   "metadata": {},
   "outputs": [
    {
     "name": "stderr",
     "output_type": "stream",
     "text": [
      "ERROR:root:Exception while sending command.\n",
      "Traceback (most recent call last):\n",
      "  File \"/opt/spark/python/lib/py4j-0.10.7-src.zip/py4j/java_gateway.py\", line 1159, in send_command\n",
      "    raise Py4JNetworkError(\"Answer from Java side is empty\")\n",
      "py4j.protocol.Py4JNetworkError: Answer from Java side is empty\n",
      "\n",
      "During handling of the above exception, another exception occurred:\n",
      "\n",
      "Traceback (most recent call last):\n",
      "  File \"/opt/spark/python/lib/py4j-0.10.7-src.zip/py4j/java_gateway.py\", line 985, in send_command\n",
      "    response = connection.send_command(command)\n",
      "  File \"/opt/spark/python/lib/py4j-0.10.7-src.zip/py4j/java_gateway.py\", line 1164, in send_command\n",
      "    \"Error while receiving\", e, proto.ERROR_ON_RECEIVE)\n",
      "py4j.protocol.Py4JNetworkError: Error while receiving\n",
      "ERROR:py4j.java_gateway:An error occurred while trying to connect to the Java server (127.0.0.1:39031)\n",
      "Traceback (most recent call last):\n",
      "  File \"/opt/conda/lib/python3.7/site-packages/IPython/core/interactiveshell.py\", line 3331, in run_code\n",
      "    exec(code_obj, self.user_global_ns, self.user_ns)\n",
      "  File \"<ipython-input-18-12ee3fb1134d>\", line 1, in <module>\n",
      "    df_mes.show(5)\n",
      "  File \"/opt/spark/python/pyspark/sql/dataframe.py\", line 378, in show\n",
      "    print(self._jdf.showString(n, 20, vertical))\n",
      "  File \"/opt/spark/python/lib/py4j-0.10.7-src.zip/py4j/java_gateway.py\", line 1257, in __call__\n",
      "    answer, self.gateway_client, self.target_id, self.name)\n",
      "  File \"/opt/spark/python/pyspark/sql/utils.py\", line 63, in deco\n",
      "    return f(*a, **kw)\n",
      "  File \"/opt/spark/python/lib/py4j-0.10.7-src.zip/py4j/protocol.py\", line 336, in get_return_value\n",
      "    format(target_id, \".\", name))\n",
      "py4j.protocol.Py4JError: An error occurred while calling o242.showString\n",
      "\n",
      "During handling of the above exception, another exception occurred:\n",
      "\n",
      "Traceback (most recent call last):\n",
      "  File \"/opt/conda/lib/python3.7/site-packages/IPython/core/interactiveshell.py\", line 2044, in showtraceback\n",
      "    stb = value._render_traceback_()\n",
      "AttributeError: 'Py4JError' object has no attribute '_render_traceback_'\n",
      "\n",
      "During handling of the above exception, another exception occurred:\n",
      "\n",
      "Traceback (most recent call last):\n",
      "  File \"/opt/spark/python/lib/py4j-0.10.7-src.zip/py4j/java_gateway.py\", line 929, in _get_connection\n",
      "    connection = self.deque.pop()\n",
      "IndexError: pop from an empty deque\n",
      "\n",
      "During handling of the above exception, another exception occurred:\n",
      "\n",
      "Traceback (most recent call last):\n",
      "  File \"/opt/spark/python/lib/py4j-0.10.7-src.zip/py4j/java_gateway.py\", line 1067, in start\n",
      "    self.socket.connect((self.address, self.port))\n",
      "ConnectionRefusedError: [Errno 111] Connection refused\n",
      "ERROR:py4j.java_gateway:An error occurred while trying to connect to the Java server (127.0.0.1:39031)\n",
      "Traceback (most recent call last):\n",
      "  File \"/opt/conda/lib/python3.7/site-packages/IPython/core/interactiveshell.py\", line 3331, in run_code\n",
      "    exec(code_obj, self.user_global_ns, self.user_ns)\n",
      "  File \"<ipython-input-18-12ee3fb1134d>\", line 1, in <module>\n",
      "    df_mes.show(5)\n",
      "  File \"/opt/spark/python/pyspark/sql/dataframe.py\", line 378, in show\n",
      "    print(self._jdf.showString(n, 20, vertical))\n",
      "  File \"/opt/spark/python/lib/py4j-0.10.7-src.zip/py4j/java_gateway.py\", line 1257, in __call__\n",
      "    answer, self.gateway_client, self.target_id, self.name)\n",
      "  File \"/opt/spark/python/pyspark/sql/utils.py\", line 63, in deco\n",
      "    return f(*a, **kw)\n",
      "  File \"/opt/spark/python/lib/py4j-0.10.7-src.zip/py4j/protocol.py\", line 336, in get_return_value\n",
      "    format(target_id, \".\", name))\n",
      "py4j.protocol.Py4JError: An error occurred while calling o242.showString\n",
      "\n",
      "During handling of the above exception, another exception occurred:\n",
      "\n",
      "Traceback (most recent call last):\n",
      "  File \"/opt/conda/lib/python3.7/site-packages/IPython/core/interactiveshell.py\", line 2044, in showtraceback\n",
      "    stb = value._render_traceback_()\n",
      "AttributeError: 'Py4JError' object has no attribute '_render_traceback_'\n",
      "\n",
      "During handling of the above exception, another exception occurred:\n",
      "\n",
      "Traceback (most recent call last):\n",
      "  File \"/opt/spark/python/lib/py4j-0.10.7-src.zip/py4j/java_gateway.py\", line 929, in _get_connection\n",
      "    connection = self.deque.pop()\n",
      "IndexError: pop from an empty deque\n",
      "\n",
      "During handling of the above exception, another exception occurred:\n",
      "\n",
      "Traceback (most recent call last):\n",
      "  File \"/opt/spark/python/lib/py4j-0.10.7-src.zip/py4j/java_gateway.py\", line 1067, in start\n",
      "    self.socket.connect((self.address, self.port))\n",
      "ConnectionRefusedError: [Errno 111] Connection refused\n",
      "ERROR:py4j.java_gateway:An error occurred while trying to connect to the Java server (127.0.0.1:39031)\n",
      "Traceback (most recent call last):\n",
      "  File \"/opt/conda/lib/python3.7/site-packages/IPython/core/interactiveshell.py\", line 3331, in run_code\n",
      "    exec(code_obj, self.user_global_ns, self.user_ns)\n",
      "  File \"<ipython-input-18-12ee3fb1134d>\", line 1, in <module>\n",
      "    df_mes.show(5)\n",
      "  File \"/opt/spark/python/pyspark/sql/dataframe.py\", line 378, in show\n",
      "    print(self._jdf.showString(n, 20, vertical))\n",
      "  File \"/opt/spark/python/lib/py4j-0.10.7-src.zip/py4j/java_gateway.py\", line 1257, in __call__\n",
      "    answer, self.gateway_client, self.target_id, self.name)\n",
      "  File \"/opt/spark/python/pyspark/sql/utils.py\", line 63, in deco\n",
      "    return f(*a, **kw)\n",
      "  File \"/opt/spark/python/lib/py4j-0.10.7-src.zip/py4j/protocol.py\", line 336, in get_return_value\n",
      "    format(target_id, \".\", name))\n",
      "py4j.protocol.Py4JError: An error occurred while calling o242.showString\n",
      "\n",
      "During handling of the above exception, another exception occurred:\n",
      "\n",
      "Traceback (most recent call last):\n",
      "  File \"/opt/conda/lib/python3.7/site-packages/IPython/core/interactiveshell.py\", line 2044, in showtraceback\n",
      "    stb = value._render_traceback_()\n",
      "AttributeError: 'Py4JError' object has no attribute '_render_traceback_'\n",
      "\n",
      "During handling of the above exception, another exception occurred:\n",
      "\n",
      "Traceback (most recent call last):\n",
      "  File \"/opt/spark/python/lib/py4j-0.10.7-src.zip/py4j/java_gateway.py\", line 929, in _get_connection\n",
      "    connection = self.deque.pop()\n",
      "IndexError: pop from an empty deque\n",
      "\n",
      "During handling of the above exception, another exception occurred:\n",
      "\n",
      "Traceback (most recent call last):\n",
      "  File \"/opt/spark/python/lib/py4j-0.10.7-src.zip/py4j/java_gateway.py\", line 1067, in start\n",
      "    self.socket.connect((self.address, self.port))\n",
      "ConnectionRefusedError: [Errno 111] Connection refused\n",
      "ERROR:py4j.java_gateway:An error occurred while trying to connect to the Java server (127.0.0.1:39031)\n",
      "Traceback (most recent call last):\n",
      "  File \"/opt/conda/lib/python3.7/site-packages/IPython/core/interactiveshell.py\", line 3331, in run_code\n",
      "    exec(code_obj, self.user_global_ns, self.user_ns)\n",
      "  File \"<ipython-input-18-12ee3fb1134d>\", line 1, in <module>\n",
      "    df_mes.show(5)\n",
      "  File \"/opt/spark/python/pyspark/sql/dataframe.py\", line 378, in show\n",
      "    print(self._jdf.showString(n, 20, vertical))\n",
      "  File \"/opt/spark/python/lib/py4j-0.10.7-src.zip/py4j/java_gateway.py\", line 1257, in __call__\n",
      "    answer, self.gateway_client, self.target_id, self.name)\n",
      "  File \"/opt/spark/python/pyspark/sql/utils.py\", line 63, in deco\n",
      "    return f(*a, **kw)\n",
      "  File \"/opt/spark/python/lib/py4j-0.10.7-src.zip/py4j/protocol.py\", line 336, in get_return_value\n",
      "    format(target_id, \".\", name))\n",
      "py4j.protocol.Py4JError: An error occurred while calling o242.showString\n",
      "\n",
      "During handling of the above exception, another exception occurred:\n",
      "\n",
      "Traceback (most recent call last):\n",
      "  File \"/opt/conda/lib/python3.7/site-packages/IPython/core/interactiveshell.py\", line 2044, in showtraceback\n",
      "    stb = value._render_traceback_()\n",
      "AttributeError: 'Py4JError' object has no attribute '_render_traceback_'\n",
      "\n",
      "During handling of the above exception, another exception occurred:\n",
      "\n",
      "Traceback (most recent call last):\n",
      "  File \"/opt/spark/python/lib/py4j-0.10.7-src.zip/py4j/java_gateway.py\", line 929, in _get_connection\n",
      "    connection = self.deque.pop()\n",
      "IndexError: pop from an empty deque\n",
      "\n",
      "During handling of the above exception, another exception occurred:\n",
      "\n",
      "Traceback (most recent call last):\n",
      "  File \"/opt/spark/python/lib/py4j-0.10.7-src.zip/py4j/java_gateway.py\", line 1067, in start\n",
      "    self.socket.connect((self.address, self.port))\n",
      "ConnectionRefusedError: [Errno 111] Connection refused\n",
      "ERROR:py4j.java_gateway:An error occurred while trying to connect to the Java server (127.0.0.1:39031)\n",
      "Traceback (most recent call last):\n",
      "  File \"/opt/conda/lib/python3.7/site-packages/IPython/core/interactiveshell.py\", line 3331, in run_code\n",
      "    exec(code_obj, self.user_global_ns, self.user_ns)\n",
      "  File \"<ipython-input-18-12ee3fb1134d>\", line 1, in <module>\n",
      "    df_mes.show(5)\n",
      "  File \"/opt/spark/python/pyspark/sql/dataframe.py\", line 378, in show\n",
      "    print(self._jdf.showString(n, 20, vertical))\n",
      "  File \"/opt/spark/python/lib/py4j-0.10.7-src.zip/py4j/java_gateway.py\", line 1257, in __call__\n",
      "    answer, self.gateway_client, self.target_id, self.name)\n",
      "  File \"/opt/spark/python/pyspark/sql/utils.py\", line 63, in deco\n",
      "    return f(*a, **kw)\n",
      "  File \"/opt/spark/python/lib/py4j-0.10.7-src.zip/py4j/protocol.py\", line 336, in get_return_value\n",
      "    format(target_id, \".\", name))\n",
      "py4j.protocol.Py4JError: An error occurred while calling o242.showString\n",
      "\n",
      "During handling of the above exception, another exception occurred:\n",
      "\n",
      "Traceback (most recent call last):\n",
      "  File \"/opt/conda/lib/python3.7/site-packages/IPython/core/interactiveshell.py\", line 2044, in showtraceback\n",
      "    stb = value._render_traceback_()\n",
      "AttributeError: 'Py4JError' object has no attribute '_render_traceback_'\n",
      "\n",
      "During handling of the above exception, another exception occurred:\n",
      "\n",
      "Traceback (most recent call last):\n",
      "  File \"/opt/spark/python/lib/py4j-0.10.7-src.zip/py4j/java_gateway.py\", line 929, in _get_connection\n",
      "    connection = self.deque.pop()\n",
      "IndexError: pop from an empty deque\n",
      "\n",
      "During handling of the above exception, another exception occurred:\n",
      "\n",
      "Traceback (most recent call last):\n",
      "  File \"/opt/spark/python/lib/py4j-0.10.7-src.zip/py4j/java_gateway.py\", line 1067, in start\n",
      "    self.socket.connect((self.address, self.port))\n",
      "ConnectionRefusedError: [Errno 111] Connection refused\n"
     ]
    },
    {
     "name": "stderr",
     "output_type": "stream",
     "text": [
      "ERROR:py4j.java_gateway:An error occurred while trying to connect to the Java server (127.0.0.1:39031)\n",
      "Traceback (most recent call last):\n",
      "  File \"/opt/conda/lib/python3.7/site-packages/IPython/core/interactiveshell.py\", line 3331, in run_code\n",
      "    exec(code_obj, self.user_global_ns, self.user_ns)\n",
      "  File \"<ipython-input-18-12ee3fb1134d>\", line 1, in <module>\n",
      "    df_mes.show(5)\n",
      "  File \"/opt/spark/python/pyspark/sql/dataframe.py\", line 378, in show\n",
      "    print(self._jdf.showString(n, 20, vertical))\n",
      "  File \"/opt/spark/python/lib/py4j-0.10.7-src.zip/py4j/java_gateway.py\", line 1257, in __call__\n",
      "    answer, self.gateway_client, self.target_id, self.name)\n",
      "  File \"/opt/spark/python/pyspark/sql/utils.py\", line 63, in deco\n",
      "    return f(*a, **kw)\n",
      "  File \"/opt/spark/python/lib/py4j-0.10.7-src.zip/py4j/protocol.py\", line 336, in get_return_value\n",
      "    format(target_id, \".\", name))\n",
      "py4j.protocol.Py4JError: An error occurred while calling o242.showString\n",
      "\n",
      "During handling of the above exception, another exception occurred:\n",
      "\n",
      "Traceback (most recent call last):\n",
      "  File \"/opt/conda/lib/python3.7/site-packages/IPython/core/interactiveshell.py\", line 2044, in showtraceback\n",
      "    stb = value._render_traceback_()\n",
      "AttributeError: 'Py4JError' object has no attribute '_render_traceback_'\n",
      "\n",
      "During handling of the above exception, another exception occurred:\n",
      "\n",
      "Traceback (most recent call last):\n",
      "  File \"/opt/spark/python/lib/py4j-0.10.7-src.zip/py4j/java_gateway.py\", line 929, in _get_connection\n",
      "    connection = self.deque.pop()\n",
      "IndexError: pop from an empty deque\n",
      "\n",
      "During handling of the above exception, another exception occurred:\n",
      "\n",
      "Traceback (most recent call last):\n",
      "  File \"/opt/spark/python/lib/py4j-0.10.7-src.zip/py4j/java_gateway.py\", line 1067, in start\n",
      "    self.socket.connect((self.address, self.port))\n",
      "ConnectionRefusedError: [Errno 111] Connection refused\n",
      "ERROR:py4j.java_gateway:An error occurred while trying to connect to the Java server (127.0.0.1:39031)\n",
      "Traceback (most recent call last):\n",
      "  File \"/opt/conda/lib/python3.7/site-packages/IPython/core/interactiveshell.py\", line 3331, in run_code\n",
      "    exec(code_obj, self.user_global_ns, self.user_ns)\n",
      "  File \"<ipython-input-18-12ee3fb1134d>\", line 1, in <module>\n",
      "    df_mes.show(5)\n",
      "  File \"/opt/spark/python/pyspark/sql/dataframe.py\", line 378, in show\n",
      "    print(self._jdf.showString(n, 20, vertical))\n",
      "  File \"/opt/spark/python/lib/py4j-0.10.7-src.zip/py4j/java_gateway.py\", line 1257, in __call__\n",
      "    answer, self.gateway_client, self.target_id, self.name)\n",
      "  File \"/opt/spark/python/pyspark/sql/utils.py\", line 63, in deco\n",
      "    return f(*a, **kw)\n",
      "  File \"/opt/spark/python/lib/py4j-0.10.7-src.zip/py4j/protocol.py\", line 336, in get_return_value\n",
      "    format(target_id, \".\", name))\n",
      "py4j.protocol.Py4JError: An error occurred while calling o242.showString\n",
      "\n",
      "During handling of the above exception, another exception occurred:\n",
      "\n",
      "Traceback (most recent call last):\n",
      "  File \"/opt/conda/lib/python3.7/site-packages/IPython/core/interactiveshell.py\", line 2044, in showtraceback\n",
      "    stb = value._render_traceback_()\n",
      "AttributeError: 'Py4JError' object has no attribute '_render_traceback_'\n",
      "\n",
      "During handling of the above exception, another exception occurred:\n",
      "\n",
      "Traceback (most recent call last):\n",
      "  File \"/opt/spark/python/lib/py4j-0.10.7-src.zip/py4j/java_gateway.py\", line 929, in _get_connection\n",
      "    connection = self.deque.pop()\n",
      "IndexError: pop from an empty deque\n",
      "\n",
      "During handling of the above exception, another exception occurred:\n",
      "\n",
      "Traceback (most recent call last):\n",
      "  File \"/opt/spark/python/lib/py4j-0.10.7-src.zip/py4j/java_gateway.py\", line 1067, in start\n",
      "    self.socket.connect((self.address, self.port))\n",
      "ConnectionRefusedError: [Errno 111] Connection refused\n",
      "ERROR:py4j.java_gateway:An error occurred while trying to connect to the Java server (127.0.0.1:39031)\n",
      "Traceback (most recent call last):\n",
      "  File \"/opt/conda/lib/python3.7/site-packages/IPython/core/interactiveshell.py\", line 3331, in run_code\n",
      "    exec(code_obj, self.user_global_ns, self.user_ns)\n",
      "  File \"<ipython-input-18-12ee3fb1134d>\", line 1, in <module>\n",
      "    df_mes.show(5)\n",
      "  File \"/opt/spark/python/pyspark/sql/dataframe.py\", line 378, in show\n",
      "    print(self._jdf.showString(n, 20, vertical))\n",
      "  File \"/opt/spark/python/lib/py4j-0.10.7-src.zip/py4j/java_gateway.py\", line 1257, in __call__\n",
      "    answer, self.gateway_client, self.target_id, self.name)\n",
      "  File \"/opt/spark/python/pyspark/sql/utils.py\", line 63, in deco\n",
      "    return f(*a, **kw)\n",
      "  File \"/opt/spark/python/lib/py4j-0.10.7-src.zip/py4j/protocol.py\", line 336, in get_return_value\n",
      "    format(target_id, \".\", name))\n",
      "py4j.protocol.Py4JError: An error occurred while calling o242.showString\n",
      "\n",
      "During handling of the above exception, another exception occurred:\n",
      "\n",
      "Traceback (most recent call last):\n",
      "  File \"/opt/conda/lib/python3.7/site-packages/IPython/core/interactiveshell.py\", line 2044, in showtraceback\n",
      "    stb = value._render_traceback_()\n",
      "AttributeError: 'Py4JError' object has no attribute '_render_traceback_'\n",
      "\n",
      "During handling of the above exception, another exception occurred:\n",
      "\n",
      "Traceback (most recent call last):\n",
      "  File \"/opt/spark/python/lib/py4j-0.10.7-src.zip/py4j/java_gateway.py\", line 929, in _get_connection\n",
      "    connection = self.deque.pop()\n",
      "IndexError: pop from an empty deque\n",
      "\n",
      "During handling of the above exception, another exception occurred:\n",
      "\n",
      "Traceback (most recent call last):\n",
      "  File \"/opt/spark/python/lib/py4j-0.10.7-src.zip/py4j/java_gateway.py\", line 1067, in start\n",
      "    self.socket.connect((self.address, self.port))\n",
      "ConnectionRefusedError: [Errno 111] Connection refused\n",
      "ERROR:py4j.java_gateway:An error occurred while trying to connect to the Java server (127.0.0.1:39031)\n",
      "Traceback (most recent call last):\n",
      "  File \"/opt/conda/lib/python3.7/site-packages/IPython/core/interactiveshell.py\", line 3331, in run_code\n",
      "    exec(code_obj, self.user_global_ns, self.user_ns)\n",
      "  File \"<ipython-input-18-12ee3fb1134d>\", line 1, in <module>\n",
      "    df_mes.show(5)\n",
      "  File \"/opt/spark/python/pyspark/sql/dataframe.py\", line 378, in show\n",
      "    print(self._jdf.showString(n, 20, vertical))\n",
      "  File \"/opt/spark/python/lib/py4j-0.10.7-src.zip/py4j/java_gateway.py\", line 1257, in __call__\n",
      "    answer, self.gateway_client, self.target_id, self.name)\n",
      "  File \"/opt/spark/python/pyspark/sql/utils.py\", line 63, in deco\n",
      "    return f(*a, **kw)\n",
      "  File \"/opt/spark/python/lib/py4j-0.10.7-src.zip/py4j/protocol.py\", line 336, in get_return_value\n",
      "    format(target_id, \".\", name))\n",
      "py4j.protocol.Py4JError: An error occurred while calling o242.showString\n",
      "\n",
      "During handling of the above exception, another exception occurred:\n",
      "\n",
      "Traceback (most recent call last):\n",
      "  File \"/opt/conda/lib/python3.7/site-packages/IPython/core/interactiveshell.py\", line 2044, in showtraceback\n",
      "    stb = value._render_traceback_()\n",
      "AttributeError: 'Py4JError' object has no attribute '_render_traceback_'\n",
      "\n",
      "During handling of the above exception, another exception occurred:\n",
      "\n",
      "Traceback (most recent call last):\n",
      "  File \"/opt/spark/python/lib/py4j-0.10.7-src.zip/py4j/java_gateway.py\", line 929, in _get_connection\n",
      "    connection = self.deque.pop()\n",
      "IndexError: pop from an empty deque\n",
      "\n",
      "During handling of the above exception, another exception occurred:\n",
      "\n",
      "Traceback (most recent call last):\n",
      "  File \"/opt/spark/python/lib/py4j-0.10.7-src.zip/py4j/java_gateway.py\", line 1067, in start\n",
      "    self.socket.connect((self.address, self.port))\n",
      "ConnectionRefusedError: [Errno 111] Connection refused\n",
      "ERROR:py4j.java_gateway:An error occurred while trying to connect to the Java server (127.0.0.1:39031)\n",
      "Traceback (most recent call last):\n",
      "  File \"/opt/conda/lib/python3.7/site-packages/IPython/core/interactiveshell.py\", line 3331, in run_code\n",
      "    exec(code_obj, self.user_global_ns, self.user_ns)\n",
      "  File \"<ipython-input-18-12ee3fb1134d>\", line 1, in <module>\n",
      "    df_mes.show(5)\n",
      "  File \"/opt/spark/python/pyspark/sql/dataframe.py\", line 378, in show\n",
      "    print(self._jdf.showString(n, 20, vertical))\n",
      "  File \"/opt/spark/python/lib/py4j-0.10.7-src.zip/py4j/java_gateway.py\", line 1257, in __call__\n",
      "    answer, self.gateway_client, self.target_id, self.name)\n",
      "  File \"/opt/spark/python/pyspark/sql/utils.py\", line 63, in deco\n",
      "    return f(*a, **kw)\n",
      "  File \"/opt/spark/python/lib/py4j-0.10.7-src.zip/py4j/protocol.py\", line 336, in get_return_value\n",
      "    format(target_id, \".\", name))\n",
      "py4j.protocol.Py4JError: An error occurred while calling o242.showString\n",
      "\n",
      "During handling of the above exception, another exception occurred:\n",
      "\n",
      "Traceback (most recent call last):\n",
      "  File \"/opt/conda/lib/python3.7/site-packages/IPython/core/interactiveshell.py\", line 2044, in showtraceback\n",
      "    stb = value._render_traceback_()\n",
      "AttributeError: 'Py4JError' object has no attribute '_render_traceback_'\n",
      "\n",
      "During handling of the above exception, another exception occurred:\n",
      "\n",
      "Traceback (most recent call last):\n",
      "  File \"/opt/spark/python/lib/py4j-0.10.7-src.zip/py4j/java_gateway.py\", line 929, in _get_connection\n",
      "    connection = self.deque.pop()\n",
      "IndexError: pop from an empty deque\n",
      "\n",
      "During handling of the above exception, another exception occurred:\n",
      "\n",
      "Traceback (most recent call last):\n",
      "  File \"/opt/spark/python/lib/py4j-0.10.7-src.zip/py4j/java_gateway.py\", line 1067, in start\n",
      "    self.socket.connect((self.address, self.port))\n",
      "ConnectionRefusedError: [Errno 111] Connection refused\n"
     ]
    },
    {
     "name": "stderr",
     "output_type": "stream",
     "text": [
      "ERROR:py4j.java_gateway:An error occurred while trying to connect to the Java server (127.0.0.1:39031)\n",
      "Traceback (most recent call last):\n",
      "  File \"/opt/conda/lib/python3.7/site-packages/IPython/core/interactiveshell.py\", line 3331, in run_code\n",
      "    exec(code_obj, self.user_global_ns, self.user_ns)\n",
      "  File \"<ipython-input-18-12ee3fb1134d>\", line 1, in <module>\n",
      "    df_mes.show(5)\n",
      "  File \"/opt/spark/python/pyspark/sql/dataframe.py\", line 378, in show\n",
      "    print(self._jdf.showString(n, 20, vertical))\n",
      "  File \"/opt/spark/python/lib/py4j-0.10.7-src.zip/py4j/java_gateway.py\", line 1257, in __call__\n",
      "    answer, self.gateway_client, self.target_id, self.name)\n",
      "  File \"/opt/spark/python/pyspark/sql/utils.py\", line 63, in deco\n",
      "    return f(*a, **kw)\n",
      "  File \"/opt/spark/python/lib/py4j-0.10.7-src.zip/py4j/protocol.py\", line 336, in get_return_value\n",
      "    format(target_id, \".\", name))\n",
      "py4j.protocol.Py4JError: An error occurred while calling o242.showString\n",
      "\n",
      "During handling of the above exception, another exception occurred:\n",
      "\n",
      "Traceback (most recent call last):\n",
      "  File \"/opt/conda/lib/python3.7/site-packages/IPython/core/interactiveshell.py\", line 2044, in showtraceback\n",
      "    stb = value._render_traceback_()\n",
      "AttributeError: 'Py4JError' object has no attribute '_render_traceback_'\n",
      "\n",
      "During handling of the above exception, another exception occurred:\n",
      "\n",
      "Traceback (most recent call last):\n",
      "  File \"/opt/spark/python/lib/py4j-0.10.7-src.zip/py4j/java_gateway.py\", line 929, in _get_connection\n",
      "    connection = self.deque.pop()\n",
      "IndexError: pop from an empty deque\n",
      "\n",
      "During handling of the above exception, another exception occurred:\n",
      "\n",
      "Traceback (most recent call last):\n",
      "  File \"/opt/spark/python/lib/py4j-0.10.7-src.zip/py4j/java_gateway.py\", line 1067, in start\n",
      "    self.socket.connect((self.address, self.port))\n",
      "ConnectionRefusedError: [Errno 111] Connection refused\n",
      "ERROR:py4j.java_gateway:An error occurred while trying to connect to the Java server (127.0.0.1:39031)\n",
      "Traceback (most recent call last):\n",
      "  File \"/opt/conda/lib/python3.7/site-packages/IPython/core/interactiveshell.py\", line 3331, in run_code\n",
      "    exec(code_obj, self.user_global_ns, self.user_ns)\n",
      "  File \"<ipython-input-18-12ee3fb1134d>\", line 1, in <module>\n",
      "    df_mes.show(5)\n",
      "  File \"/opt/spark/python/pyspark/sql/dataframe.py\", line 378, in show\n",
      "    print(self._jdf.showString(n, 20, vertical))\n",
      "  File \"/opt/spark/python/lib/py4j-0.10.7-src.zip/py4j/java_gateway.py\", line 1257, in __call__\n",
      "    answer, self.gateway_client, self.target_id, self.name)\n",
      "  File \"/opt/spark/python/pyspark/sql/utils.py\", line 63, in deco\n",
      "    return f(*a, **kw)\n",
      "  File \"/opt/spark/python/lib/py4j-0.10.7-src.zip/py4j/protocol.py\", line 336, in get_return_value\n",
      "    format(target_id, \".\", name))\n",
      "py4j.protocol.Py4JError: An error occurred while calling o242.showString\n",
      "\n",
      "During handling of the above exception, another exception occurred:\n",
      "\n",
      "Traceback (most recent call last):\n",
      "  File \"/opt/conda/lib/python3.7/site-packages/IPython/core/interactiveshell.py\", line 2044, in showtraceback\n",
      "    stb = value._render_traceback_()\n",
      "AttributeError: 'Py4JError' object has no attribute '_render_traceback_'\n",
      "\n",
      "During handling of the above exception, another exception occurred:\n",
      "\n",
      "Traceback (most recent call last):\n",
      "  File \"/opt/spark/python/lib/py4j-0.10.7-src.zip/py4j/java_gateway.py\", line 929, in _get_connection\n",
      "    connection = self.deque.pop()\n",
      "IndexError: pop from an empty deque\n",
      "\n",
      "During handling of the above exception, another exception occurred:\n",
      "\n",
      "Traceback (most recent call last):\n",
      "  File \"/opt/spark/python/lib/py4j-0.10.7-src.zip/py4j/java_gateway.py\", line 1067, in start\n",
      "    self.socket.connect((self.address, self.port))\n",
      "ConnectionRefusedError: [Errno 111] Connection refused\n",
      "ERROR:py4j.java_gateway:An error occurred while trying to connect to the Java server (127.0.0.1:39031)\n",
      "Traceback (most recent call last):\n",
      "  File \"/opt/conda/lib/python3.7/site-packages/IPython/core/interactiveshell.py\", line 3331, in run_code\n",
      "    exec(code_obj, self.user_global_ns, self.user_ns)\n",
      "  File \"<ipython-input-18-12ee3fb1134d>\", line 1, in <module>\n",
      "    df_mes.show(5)\n",
      "  File \"/opt/spark/python/pyspark/sql/dataframe.py\", line 378, in show\n",
      "    print(self._jdf.showString(n, 20, vertical))\n",
      "  File \"/opt/spark/python/lib/py4j-0.10.7-src.zip/py4j/java_gateway.py\", line 1257, in __call__\n",
      "    answer, self.gateway_client, self.target_id, self.name)\n",
      "  File \"/opt/spark/python/pyspark/sql/utils.py\", line 63, in deco\n",
      "    return f(*a, **kw)\n",
      "  File \"/opt/spark/python/lib/py4j-0.10.7-src.zip/py4j/protocol.py\", line 336, in get_return_value\n",
      "    format(target_id, \".\", name))\n",
      "py4j.protocol.Py4JError: An error occurred while calling o242.showString\n",
      "\n",
      "During handling of the above exception, another exception occurred:\n",
      "\n",
      "Traceback (most recent call last):\n",
      "  File \"/opt/conda/lib/python3.7/site-packages/IPython/core/interactiveshell.py\", line 2044, in showtraceback\n",
      "    stb = value._render_traceback_()\n",
      "AttributeError: 'Py4JError' object has no attribute '_render_traceback_'\n",
      "\n",
      "During handling of the above exception, another exception occurred:\n",
      "\n",
      "Traceback (most recent call last):\n",
      "  File \"/opt/spark/python/lib/py4j-0.10.7-src.zip/py4j/java_gateway.py\", line 929, in _get_connection\n",
      "    connection = self.deque.pop()\n",
      "IndexError: pop from an empty deque\n",
      "\n",
      "During handling of the above exception, another exception occurred:\n",
      "\n",
      "Traceback (most recent call last):\n",
      "  File \"/opt/spark/python/lib/py4j-0.10.7-src.zip/py4j/java_gateway.py\", line 1067, in start\n",
      "    self.socket.connect((self.address, self.port))\n",
      "ConnectionRefusedError: [Errno 111] Connection refused\n",
      "ERROR:py4j.java_gateway:An error occurred while trying to connect to the Java server (127.0.0.1:39031)\n",
      "Traceback (most recent call last):\n",
      "  File \"/opt/conda/lib/python3.7/site-packages/IPython/core/interactiveshell.py\", line 3331, in run_code\n",
      "    exec(code_obj, self.user_global_ns, self.user_ns)\n",
      "  File \"<ipython-input-18-12ee3fb1134d>\", line 1, in <module>\n",
      "    df_mes.show(5)\n",
      "  File \"/opt/spark/python/pyspark/sql/dataframe.py\", line 378, in show\n",
      "    print(self._jdf.showString(n, 20, vertical))\n",
      "  File \"/opt/spark/python/lib/py4j-0.10.7-src.zip/py4j/java_gateway.py\", line 1257, in __call__\n",
      "    answer, self.gateway_client, self.target_id, self.name)\n",
      "  File \"/opt/spark/python/pyspark/sql/utils.py\", line 63, in deco\n",
      "    return f(*a, **kw)\n",
      "  File \"/opt/spark/python/lib/py4j-0.10.7-src.zip/py4j/protocol.py\", line 336, in get_return_value\n",
      "    format(target_id, \".\", name))\n",
      "py4j.protocol.Py4JError: An error occurred while calling o242.showString\n",
      "\n",
      "During handling of the above exception, another exception occurred:\n",
      "\n",
      "Traceback (most recent call last):\n",
      "  File \"/opt/conda/lib/python3.7/site-packages/IPython/core/interactiveshell.py\", line 2044, in showtraceback\n",
      "    stb = value._render_traceback_()\n",
      "AttributeError: 'Py4JError' object has no attribute '_render_traceback_'\n",
      "\n",
      "During handling of the above exception, another exception occurred:\n",
      "\n",
      "Traceback (most recent call last):\n",
      "  File \"/opt/spark/python/lib/py4j-0.10.7-src.zip/py4j/java_gateway.py\", line 929, in _get_connection\n",
      "    connection = self.deque.pop()\n",
      "IndexError: pop from an empty deque\n",
      "\n",
      "During handling of the above exception, another exception occurred:\n",
      "\n",
      "Traceback (most recent call last):\n",
      "  File \"/opt/spark/python/lib/py4j-0.10.7-src.zip/py4j/java_gateway.py\", line 1067, in start\n",
      "    self.socket.connect((self.address, self.port))\n",
      "ConnectionRefusedError: [Errno 111] Connection refused\n",
      "ERROR:py4j.java_gateway:An error occurred while trying to connect to the Java server (127.0.0.1:39031)\n",
      "Traceback (most recent call last):\n",
      "  File \"/opt/conda/lib/python3.7/site-packages/IPython/core/interactiveshell.py\", line 3331, in run_code\n",
      "    exec(code_obj, self.user_global_ns, self.user_ns)\n",
      "  File \"<ipython-input-18-12ee3fb1134d>\", line 1, in <module>\n",
      "    df_mes.show(5)\n",
      "  File \"/opt/spark/python/pyspark/sql/dataframe.py\", line 378, in show\n",
      "    print(self._jdf.showString(n, 20, vertical))\n",
      "  File \"/opt/spark/python/lib/py4j-0.10.7-src.zip/py4j/java_gateway.py\", line 1257, in __call__\n",
      "    answer, self.gateway_client, self.target_id, self.name)\n",
      "  File \"/opt/spark/python/pyspark/sql/utils.py\", line 63, in deco\n",
      "    return f(*a, **kw)\n",
      "  File \"/opt/spark/python/lib/py4j-0.10.7-src.zip/py4j/protocol.py\", line 336, in get_return_value\n",
      "    format(target_id, \".\", name))\n",
      "py4j.protocol.Py4JError: An error occurred while calling o242.showString\n",
      "\n",
      "During handling of the above exception, another exception occurred:\n",
      "\n",
      "Traceback (most recent call last):\n",
      "  File \"/opt/conda/lib/python3.7/site-packages/IPython/core/interactiveshell.py\", line 2044, in showtraceback\n",
      "    stb = value._render_traceback_()\n",
      "AttributeError: 'Py4JError' object has no attribute '_render_traceback_'\n",
      "\n",
      "During handling of the above exception, another exception occurred:\n",
      "\n",
      "Traceback (most recent call last):\n",
      "  File \"/opt/spark/python/lib/py4j-0.10.7-src.zip/py4j/java_gateway.py\", line 929, in _get_connection\n",
      "    connection = self.deque.pop()\n",
      "IndexError: pop from an empty deque\n",
      "\n",
      "During handling of the above exception, another exception occurred:\n",
      "\n",
      "Traceback (most recent call last):\n",
      "  File \"/opt/spark/python/lib/py4j-0.10.7-src.zip/py4j/java_gateway.py\", line 1067, in start\n",
      "    self.socket.connect((self.address, self.port))\n",
      "ConnectionRefusedError: [Errno 111] Connection refused\n"
     ]
    },
    {
     "name": "stderr",
     "output_type": "stream",
     "text": [
      "ERROR:py4j.java_gateway:An error occurred while trying to connect to the Java server (127.0.0.1:39031)\n",
      "Traceback (most recent call last):\n",
      "  File \"/opt/conda/lib/python3.7/site-packages/IPython/core/interactiveshell.py\", line 3331, in run_code\n",
      "    exec(code_obj, self.user_global_ns, self.user_ns)\n",
      "  File \"<ipython-input-18-12ee3fb1134d>\", line 1, in <module>\n",
      "    df_mes.show(5)\n",
      "  File \"/opt/spark/python/pyspark/sql/dataframe.py\", line 378, in show\n",
      "    print(self._jdf.showString(n, 20, vertical))\n",
      "  File \"/opt/spark/python/lib/py4j-0.10.7-src.zip/py4j/java_gateway.py\", line 1257, in __call__\n",
      "    answer, self.gateway_client, self.target_id, self.name)\n",
      "  File \"/opt/spark/python/pyspark/sql/utils.py\", line 63, in deco\n",
      "    return f(*a, **kw)\n",
      "  File \"/opt/spark/python/lib/py4j-0.10.7-src.zip/py4j/protocol.py\", line 336, in get_return_value\n",
      "    format(target_id, \".\", name))\n",
      "py4j.protocol.Py4JError: An error occurred while calling o242.showString\n",
      "\n",
      "During handling of the above exception, another exception occurred:\n",
      "\n",
      "Traceback (most recent call last):\n",
      "  File \"/opt/conda/lib/python3.7/site-packages/IPython/core/interactiveshell.py\", line 2044, in showtraceback\n",
      "    stb = value._render_traceback_()\n",
      "AttributeError: 'Py4JError' object has no attribute '_render_traceback_'\n",
      "\n",
      "During handling of the above exception, another exception occurred:\n",
      "\n",
      "Traceback (most recent call last):\n",
      "  File \"/opt/spark/python/lib/py4j-0.10.7-src.zip/py4j/java_gateway.py\", line 929, in _get_connection\n",
      "    connection = self.deque.pop()\n",
      "IndexError: pop from an empty deque\n",
      "\n",
      "During handling of the above exception, another exception occurred:\n",
      "\n",
      "Traceback (most recent call last):\n",
      "  File \"/opt/spark/python/lib/py4j-0.10.7-src.zip/py4j/java_gateway.py\", line 1067, in start\n",
      "    self.socket.connect((self.address, self.port))\n",
      "ConnectionRefusedError: [Errno 111] Connection refused\n",
      "ERROR:py4j.java_gateway:An error occurred while trying to connect to the Java server (127.0.0.1:39031)\n",
      "Traceback (most recent call last):\n",
      "  File \"/opt/conda/lib/python3.7/site-packages/IPython/core/interactiveshell.py\", line 3331, in run_code\n",
      "    exec(code_obj, self.user_global_ns, self.user_ns)\n",
      "  File \"<ipython-input-18-12ee3fb1134d>\", line 1, in <module>\n",
      "    df_mes.show(5)\n",
      "  File \"/opt/spark/python/pyspark/sql/dataframe.py\", line 378, in show\n",
      "    print(self._jdf.showString(n, 20, vertical))\n",
      "  File \"/opt/spark/python/lib/py4j-0.10.7-src.zip/py4j/java_gateway.py\", line 1257, in __call__\n",
      "    answer, self.gateway_client, self.target_id, self.name)\n",
      "  File \"/opt/spark/python/pyspark/sql/utils.py\", line 63, in deco\n",
      "    return f(*a, **kw)\n",
      "  File \"/opt/spark/python/lib/py4j-0.10.7-src.zip/py4j/protocol.py\", line 336, in get_return_value\n",
      "    format(target_id, \".\", name))\n",
      "py4j.protocol.Py4JError: An error occurred while calling o242.showString\n",
      "\n",
      "During handling of the above exception, another exception occurred:\n",
      "\n",
      "Traceback (most recent call last):\n",
      "  File \"/opt/conda/lib/python3.7/site-packages/IPython/core/interactiveshell.py\", line 2044, in showtraceback\n",
      "    stb = value._render_traceback_()\n",
      "AttributeError: 'Py4JError' object has no attribute '_render_traceback_'\n",
      "\n",
      "During handling of the above exception, another exception occurred:\n",
      "\n",
      "Traceback (most recent call last):\n",
      "  File \"/opt/spark/python/lib/py4j-0.10.7-src.zip/py4j/java_gateway.py\", line 929, in _get_connection\n",
      "    connection = self.deque.pop()\n",
      "IndexError: pop from an empty deque\n",
      "\n",
      "During handling of the above exception, another exception occurred:\n",
      "\n",
      "Traceback (most recent call last):\n",
      "  File \"/opt/spark/python/lib/py4j-0.10.7-src.zip/py4j/java_gateway.py\", line 1067, in start\n",
      "    self.socket.connect((self.address, self.port))\n",
      "ConnectionRefusedError: [Errno 111] Connection refused\n",
      "ERROR:py4j.java_gateway:An error occurred while trying to connect to the Java server (127.0.0.1:39031)\n",
      "Traceback (most recent call last):\n",
      "  File \"/opt/conda/lib/python3.7/site-packages/IPython/core/interactiveshell.py\", line 3331, in run_code\n",
      "    exec(code_obj, self.user_global_ns, self.user_ns)\n",
      "  File \"<ipython-input-18-12ee3fb1134d>\", line 1, in <module>\n",
      "    df_mes.show(5)\n",
      "  File \"/opt/spark/python/pyspark/sql/dataframe.py\", line 378, in show\n",
      "    print(self._jdf.showString(n, 20, vertical))\n",
      "  File \"/opt/spark/python/lib/py4j-0.10.7-src.zip/py4j/java_gateway.py\", line 1257, in __call__\n",
      "    answer, self.gateway_client, self.target_id, self.name)\n",
      "  File \"/opt/spark/python/pyspark/sql/utils.py\", line 63, in deco\n",
      "    return f(*a, **kw)\n",
      "  File \"/opt/spark/python/lib/py4j-0.10.7-src.zip/py4j/protocol.py\", line 336, in get_return_value\n",
      "    format(target_id, \".\", name))\n",
      "py4j.protocol.Py4JError: An error occurred while calling o242.showString\n",
      "\n",
      "During handling of the above exception, another exception occurred:\n",
      "\n",
      "Traceback (most recent call last):\n",
      "  File \"/opt/conda/lib/python3.7/site-packages/IPython/core/interactiveshell.py\", line 2044, in showtraceback\n",
      "    stb = value._render_traceback_()\n",
      "AttributeError: 'Py4JError' object has no attribute '_render_traceback_'\n",
      "\n",
      "During handling of the above exception, another exception occurred:\n",
      "\n",
      "Traceback (most recent call last):\n",
      "  File \"/opt/spark/python/lib/py4j-0.10.7-src.zip/py4j/java_gateway.py\", line 929, in _get_connection\n",
      "    connection = self.deque.pop()\n",
      "IndexError: pop from an empty deque\n",
      "\n",
      "During handling of the above exception, another exception occurred:\n",
      "\n",
      "Traceback (most recent call last):\n",
      "  File \"/opt/spark/python/lib/py4j-0.10.7-src.zip/py4j/java_gateway.py\", line 1067, in start\n",
      "    self.socket.connect((self.address, self.port))\n",
      "ConnectionRefusedError: [Errno 111] Connection refused\n",
      "ERROR:py4j.java_gateway:An error occurred while trying to connect to the Java server (127.0.0.1:39031)\n",
      "Traceback (most recent call last):\n",
      "  File \"/opt/conda/lib/python3.7/site-packages/IPython/core/interactiveshell.py\", line 3331, in run_code\n",
      "    exec(code_obj, self.user_global_ns, self.user_ns)\n",
      "  File \"<ipython-input-18-12ee3fb1134d>\", line 1, in <module>\n",
      "    df_mes.show(5)\n",
      "  File \"/opt/spark/python/pyspark/sql/dataframe.py\", line 378, in show\n",
      "    print(self._jdf.showString(n, 20, vertical))\n",
      "  File \"/opt/spark/python/lib/py4j-0.10.7-src.zip/py4j/java_gateway.py\", line 1257, in __call__\n",
      "    answer, self.gateway_client, self.target_id, self.name)\n",
      "  File \"/opt/spark/python/pyspark/sql/utils.py\", line 63, in deco\n",
      "    return f(*a, **kw)\n",
      "  File \"/opt/spark/python/lib/py4j-0.10.7-src.zip/py4j/protocol.py\", line 336, in get_return_value\n",
      "    format(target_id, \".\", name))\n",
      "py4j.protocol.Py4JError: An error occurred while calling o242.showString\n",
      "\n",
      "During handling of the above exception, another exception occurred:\n",
      "\n",
      "Traceback (most recent call last):\n",
      "  File \"/opt/conda/lib/python3.7/site-packages/IPython/core/interactiveshell.py\", line 2044, in showtraceback\n",
      "    stb = value._render_traceback_()\n",
      "AttributeError: 'Py4JError' object has no attribute '_render_traceback_'\n",
      "\n",
      "During handling of the above exception, another exception occurred:\n",
      "\n",
      "Traceback (most recent call last):\n",
      "  File \"/opt/spark/python/lib/py4j-0.10.7-src.zip/py4j/java_gateway.py\", line 929, in _get_connection\n",
      "    connection = self.deque.pop()\n",
      "IndexError: pop from an empty deque\n",
      "\n",
      "During handling of the above exception, another exception occurred:\n",
      "\n",
      "Traceback (most recent call last):\n",
      "  File \"/opt/spark/python/lib/py4j-0.10.7-src.zip/py4j/java_gateway.py\", line 1067, in start\n",
      "    self.socket.connect((self.address, self.port))\n",
      "ConnectionRefusedError: [Errno 111] Connection refused\n",
      "ERROR:py4j.java_gateway:An error occurred while trying to connect to the Java server (127.0.0.1:39031)\n",
      "Traceback (most recent call last):\n",
      "  File \"/opt/conda/lib/python3.7/site-packages/IPython/core/interactiveshell.py\", line 3331, in run_code\n",
      "    exec(code_obj, self.user_global_ns, self.user_ns)\n",
      "  File \"<ipython-input-18-12ee3fb1134d>\", line 1, in <module>\n",
      "    df_mes.show(5)\n",
      "  File \"/opt/spark/python/pyspark/sql/dataframe.py\", line 378, in show\n",
      "    print(self._jdf.showString(n, 20, vertical))\n",
      "  File \"/opt/spark/python/lib/py4j-0.10.7-src.zip/py4j/java_gateway.py\", line 1257, in __call__\n",
      "    answer, self.gateway_client, self.target_id, self.name)\n",
      "  File \"/opt/spark/python/pyspark/sql/utils.py\", line 63, in deco\n",
      "    return f(*a, **kw)\n",
      "  File \"/opt/spark/python/lib/py4j-0.10.7-src.zip/py4j/protocol.py\", line 336, in get_return_value\n",
      "    format(target_id, \".\", name))\n",
      "py4j.protocol.Py4JError: An error occurred while calling o242.showString\n",
      "\n",
      "During handling of the above exception, another exception occurred:\n",
      "\n",
      "Traceback (most recent call last):\n",
      "  File \"/opt/conda/lib/python3.7/site-packages/IPython/core/interactiveshell.py\", line 2044, in showtraceback\n",
      "    stb = value._render_traceback_()\n",
      "AttributeError: 'Py4JError' object has no attribute '_render_traceback_'\n",
      "\n",
      "During handling of the above exception, another exception occurred:\n",
      "\n",
      "Traceback (most recent call last):\n",
      "  File \"/opt/spark/python/lib/py4j-0.10.7-src.zip/py4j/java_gateway.py\", line 929, in _get_connection\n",
      "    connection = self.deque.pop()\n",
      "IndexError: pop from an empty deque\n",
      "\n",
      "During handling of the above exception, another exception occurred:\n",
      "\n",
      "Traceback (most recent call last):\n",
      "  File \"/opt/spark/python/lib/py4j-0.10.7-src.zip/py4j/java_gateway.py\", line 1067, in start\n",
      "    self.socket.connect((self.address, self.port))\n",
      "ConnectionRefusedError: [Errno 111] Connection refused\n"
     ]
    },
    {
     "name": "stderr",
     "output_type": "stream",
     "text": [
      "ERROR:py4j.java_gateway:An error occurred while trying to connect to the Java server (127.0.0.1:39031)\n",
      "Traceback (most recent call last):\n",
      "  File \"/opt/conda/lib/python3.7/site-packages/IPython/core/interactiveshell.py\", line 3331, in run_code\n",
      "    exec(code_obj, self.user_global_ns, self.user_ns)\n",
      "  File \"<ipython-input-18-12ee3fb1134d>\", line 1, in <module>\n",
      "    df_mes.show(5)\n",
      "  File \"/opt/spark/python/pyspark/sql/dataframe.py\", line 378, in show\n",
      "    print(self._jdf.showString(n, 20, vertical))\n",
      "  File \"/opt/spark/python/lib/py4j-0.10.7-src.zip/py4j/java_gateway.py\", line 1257, in __call__\n",
      "    answer, self.gateway_client, self.target_id, self.name)\n",
      "  File \"/opt/spark/python/pyspark/sql/utils.py\", line 63, in deco\n",
      "    return f(*a, **kw)\n",
      "  File \"/opt/spark/python/lib/py4j-0.10.7-src.zip/py4j/protocol.py\", line 336, in get_return_value\n",
      "    format(target_id, \".\", name))\n",
      "py4j.protocol.Py4JError: An error occurred while calling o242.showString\n",
      "\n",
      "During handling of the above exception, another exception occurred:\n",
      "\n",
      "Traceback (most recent call last):\n",
      "  File \"/opt/conda/lib/python3.7/site-packages/IPython/core/interactiveshell.py\", line 2044, in showtraceback\n",
      "    stb = value._render_traceback_()\n",
      "AttributeError: 'Py4JError' object has no attribute '_render_traceback_'\n",
      "\n",
      "During handling of the above exception, another exception occurred:\n",
      "\n",
      "Traceback (most recent call last):\n",
      "  File \"/opt/spark/python/lib/py4j-0.10.7-src.zip/py4j/java_gateway.py\", line 929, in _get_connection\n",
      "    connection = self.deque.pop()\n",
      "IndexError: pop from an empty deque\n",
      "\n",
      "During handling of the above exception, another exception occurred:\n",
      "\n",
      "Traceback (most recent call last):\n",
      "  File \"/opt/spark/python/lib/py4j-0.10.7-src.zip/py4j/java_gateway.py\", line 1067, in start\n",
      "    self.socket.connect((self.address, self.port))\n",
      "ConnectionRefusedError: [Errno 111] Connection refused\n",
      "ERROR:py4j.java_gateway:An error occurred while trying to connect to the Java server (127.0.0.1:39031)\n",
      "Traceback (most recent call last):\n",
      "  File \"/opt/conda/lib/python3.7/site-packages/IPython/core/interactiveshell.py\", line 3331, in run_code\n",
      "    exec(code_obj, self.user_global_ns, self.user_ns)\n",
      "  File \"<ipython-input-18-12ee3fb1134d>\", line 1, in <module>\n",
      "    df_mes.show(5)\n",
      "  File \"/opt/spark/python/pyspark/sql/dataframe.py\", line 378, in show\n",
      "    print(self._jdf.showString(n, 20, vertical))\n",
      "  File \"/opt/spark/python/lib/py4j-0.10.7-src.zip/py4j/java_gateway.py\", line 1257, in __call__\n",
      "    answer, self.gateway_client, self.target_id, self.name)\n",
      "  File \"/opt/spark/python/pyspark/sql/utils.py\", line 63, in deco\n",
      "    return f(*a, **kw)\n",
      "  File \"/opt/spark/python/lib/py4j-0.10.7-src.zip/py4j/protocol.py\", line 336, in get_return_value\n",
      "    format(target_id, \".\", name))\n",
      "py4j.protocol.Py4JError: An error occurred while calling o242.showString\n",
      "\n",
      "During handling of the above exception, another exception occurred:\n",
      "\n",
      "Traceback (most recent call last):\n",
      "  File \"/opt/conda/lib/python3.7/site-packages/IPython/core/interactiveshell.py\", line 2044, in showtraceback\n",
      "    stb = value._render_traceback_()\n",
      "AttributeError: 'Py4JError' object has no attribute '_render_traceback_'\n",
      "\n",
      "During handling of the above exception, another exception occurred:\n",
      "\n",
      "Traceback (most recent call last):\n",
      "  File \"/opt/spark/python/lib/py4j-0.10.7-src.zip/py4j/java_gateway.py\", line 929, in _get_connection\n",
      "    connection = self.deque.pop()\n",
      "IndexError: pop from an empty deque\n",
      "\n",
      "During handling of the above exception, another exception occurred:\n",
      "\n",
      "Traceback (most recent call last):\n",
      "  File \"/opt/spark/python/lib/py4j-0.10.7-src.zip/py4j/java_gateway.py\", line 1067, in start\n",
      "    self.socket.connect((self.address, self.port))\n",
      "ConnectionRefusedError: [Errno 111] Connection refused\n",
      "ERROR:py4j.java_gateway:An error occurred while trying to connect to the Java server (127.0.0.1:39031)\n",
      "Traceback (most recent call last):\n",
      "  File \"/opt/conda/lib/python3.7/site-packages/IPython/core/interactiveshell.py\", line 3331, in run_code\n",
      "    exec(code_obj, self.user_global_ns, self.user_ns)\n",
      "  File \"<ipython-input-18-12ee3fb1134d>\", line 1, in <module>\n",
      "    df_mes.show(5)\n",
      "  File \"/opt/spark/python/pyspark/sql/dataframe.py\", line 378, in show\n",
      "    print(self._jdf.showString(n, 20, vertical))\n",
      "  File \"/opt/spark/python/lib/py4j-0.10.7-src.zip/py4j/java_gateway.py\", line 1257, in __call__\n",
      "    answer, self.gateway_client, self.target_id, self.name)\n",
      "  File \"/opt/spark/python/pyspark/sql/utils.py\", line 63, in deco\n",
      "    return f(*a, **kw)\n",
      "  File \"/opt/spark/python/lib/py4j-0.10.7-src.zip/py4j/protocol.py\", line 336, in get_return_value\n",
      "    format(target_id, \".\", name))\n",
      "py4j.protocol.Py4JError: An error occurred while calling o242.showString\n",
      "\n",
      "During handling of the above exception, another exception occurred:\n",
      "\n",
      "Traceback (most recent call last):\n",
      "  File \"/opt/conda/lib/python3.7/site-packages/IPython/core/interactiveshell.py\", line 2044, in showtraceback\n",
      "    stb = value._render_traceback_()\n",
      "AttributeError: 'Py4JError' object has no attribute '_render_traceback_'\n",
      "\n",
      "During handling of the above exception, another exception occurred:\n",
      "\n",
      "Traceback (most recent call last):\n",
      "  File \"/opt/spark/python/lib/py4j-0.10.7-src.zip/py4j/java_gateway.py\", line 929, in _get_connection\n",
      "    connection = self.deque.pop()\n",
      "IndexError: pop from an empty deque\n",
      "\n",
      "During handling of the above exception, another exception occurred:\n",
      "\n",
      "Traceback (most recent call last):\n",
      "  File \"/opt/spark/python/lib/py4j-0.10.7-src.zip/py4j/java_gateway.py\", line 1067, in start\n",
      "    self.socket.connect((self.address, self.port))\n",
      "ConnectionRefusedError: [Errno 111] Connection refused\n",
      "ERROR:py4j.java_gateway:An error occurred while trying to connect to the Java server (127.0.0.1:39031)\n",
      "Traceback (most recent call last):\n",
      "  File \"/opt/conda/lib/python3.7/site-packages/IPython/core/interactiveshell.py\", line 3331, in run_code\n",
      "    exec(code_obj, self.user_global_ns, self.user_ns)\n",
      "  File \"<ipython-input-18-12ee3fb1134d>\", line 1, in <module>\n",
      "    df_mes.show(5)\n",
      "  File \"/opt/spark/python/pyspark/sql/dataframe.py\", line 378, in show\n",
      "    print(self._jdf.showString(n, 20, vertical))\n",
      "  File \"/opt/spark/python/lib/py4j-0.10.7-src.zip/py4j/java_gateway.py\", line 1257, in __call__\n",
      "    answer, self.gateway_client, self.target_id, self.name)\n",
      "  File \"/opt/spark/python/pyspark/sql/utils.py\", line 63, in deco\n",
      "    return f(*a, **kw)\n",
      "  File \"/opt/spark/python/lib/py4j-0.10.7-src.zip/py4j/protocol.py\", line 336, in get_return_value\n",
      "    format(target_id, \".\", name))\n",
      "py4j.protocol.Py4JError: An error occurred while calling o242.showString\n",
      "\n",
      "During handling of the above exception, another exception occurred:\n",
      "\n",
      "Traceback (most recent call last):\n",
      "  File \"/opt/conda/lib/python3.7/site-packages/IPython/core/interactiveshell.py\", line 2044, in showtraceback\n",
      "    stb = value._render_traceback_()\n",
      "AttributeError: 'Py4JError' object has no attribute '_render_traceback_'\n",
      "\n",
      "During handling of the above exception, another exception occurred:\n",
      "\n",
      "Traceback (most recent call last):\n",
      "  File \"/opt/spark/python/lib/py4j-0.10.7-src.zip/py4j/java_gateway.py\", line 929, in _get_connection\n",
      "    connection = self.deque.pop()\n",
      "IndexError: pop from an empty deque\n",
      "\n",
      "During handling of the above exception, another exception occurred:\n",
      "\n",
      "Traceback (most recent call last):\n",
      "  File \"/opt/spark/python/lib/py4j-0.10.7-src.zip/py4j/java_gateway.py\", line 1067, in start\n",
      "    self.socket.connect((self.address, self.port))\n",
      "ConnectionRefusedError: [Errno 111] Connection refused\n",
      "ERROR:py4j.java_gateway:An error occurred while trying to connect to the Java server (127.0.0.1:39031)\n",
      "Traceback (most recent call last):\n",
      "  File \"/opt/conda/lib/python3.7/site-packages/IPython/core/interactiveshell.py\", line 3331, in run_code\n",
      "    exec(code_obj, self.user_global_ns, self.user_ns)\n",
      "  File \"<ipython-input-18-12ee3fb1134d>\", line 1, in <module>\n",
      "    df_mes.show(5)\n",
      "  File \"/opt/spark/python/pyspark/sql/dataframe.py\", line 378, in show\n",
      "    print(self._jdf.showString(n, 20, vertical))\n",
      "  File \"/opt/spark/python/lib/py4j-0.10.7-src.zip/py4j/java_gateway.py\", line 1257, in __call__\n",
      "    answer, self.gateway_client, self.target_id, self.name)\n",
      "  File \"/opt/spark/python/pyspark/sql/utils.py\", line 63, in deco\n",
      "    return f(*a, **kw)\n",
      "  File \"/opt/spark/python/lib/py4j-0.10.7-src.zip/py4j/protocol.py\", line 336, in get_return_value\n",
      "    format(target_id, \".\", name))\n",
      "py4j.protocol.Py4JError: An error occurred while calling o242.showString\n",
      "\n",
      "During handling of the above exception, another exception occurred:\n",
      "\n",
      "Traceback (most recent call last):\n",
      "  File \"/opt/conda/lib/python3.7/site-packages/IPython/core/interactiveshell.py\", line 2044, in showtraceback\n",
      "    stb = value._render_traceback_()\n",
      "AttributeError: 'Py4JError' object has no attribute '_render_traceback_'\n",
      "\n",
      "During handling of the above exception, another exception occurred:\n",
      "\n",
      "Traceback (most recent call last):\n",
      "  File \"/opt/spark/python/lib/py4j-0.10.7-src.zip/py4j/java_gateway.py\", line 929, in _get_connection\n",
      "    connection = self.deque.pop()\n",
      "IndexError: pop from an empty deque\n",
      "\n",
      "During handling of the above exception, another exception occurred:\n",
      "\n",
      "Traceback (most recent call last):\n",
      "  File \"/opt/spark/python/lib/py4j-0.10.7-src.zip/py4j/java_gateway.py\", line 1067, in start\n",
      "    self.socket.connect((self.address, self.port))\n",
      "ConnectionRefusedError: [Errno 111] Connection refused\n"
     ]
    },
    {
     "name": "stderr",
     "output_type": "stream",
     "text": [
      "ERROR:py4j.java_gateway:An error occurred while trying to connect to the Java server (127.0.0.1:39031)\n",
      "Traceback (most recent call last):\n",
      "  File \"/opt/conda/lib/python3.7/site-packages/IPython/core/interactiveshell.py\", line 3331, in run_code\n",
      "    exec(code_obj, self.user_global_ns, self.user_ns)\n",
      "  File \"<ipython-input-18-12ee3fb1134d>\", line 1, in <module>\n",
      "    df_mes.show(5)\n",
      "  File \"/opt/spark/python/pyspark/sql/dataframe.py\", line 378, in show\n",
      "    print(self._jdf.showString(n, 20, vertical))\n",
      "  File \"/opt/spark/python/lib/py4j-0.10.7-src.zip/py4j/java_gateway.py\", line 1257, in __call__\n",
      "    answer, self.gateway_client, self.target_id, self.name)\n",
      "  File \"/opt/spark/python/pyspark/sql/utils.py\", line 63, in deco\n",
      "    return f(*a, **kw)\n",
      "  File \"/opt/spark/python/lib/py4j-0.10.7-src.zip/py4j/protocol.py\", line 336, in get_return_value\n",
      "    format(target_id, \".\", name))\n",
      "py4j.protocol.Py4JError: An error occurred while calling o242.showString\n",
      "\n",
      "During handling of the above exception, another exception occurred:\n",
      "\n",
      "Traceback (most recent call last):\n",
      "  File \"/opt/conda/lib/python3.7/site-packages/IPython/core/interactiveshell.py\", line 2044, in showtraceback\n",
      "    stb = value._render_traceback_()\n",
      "AttributeError: 'Py4JError' object has no attribute '_render_traceback_'\n",
      "\n",
      "During handling of the above exception, another exception occurred:\n",
      "\n",
      "Traceback (most recent call last):\n",
      "  File \"/opt/spark/python/lib/py4j-0.10.7-src.zip/py4j/java_gateway.py\", line 929, in _get_connection\n",
      "    connection = self.deque.pop()\n",
      "IndexError: pop from an empty deque\n",
      "\n",
      "During handling of the above exception, another exception occurred:\n",
      "\n",
      "Traceback (most recent call last):\n",
      "  File \"/opt/spark/python/lib/py4j-0.10.7-src.zip/py4j/java_gateway.py\", line 1067, in start\n",
      "    self.socket.connect((self.address, self.port))\n",
      "ConnectionRefusedError: [Errno 111] Connection refused\n",
      "ERROR:py4j.java_gateway:An error occurred while trying to connect to the Java server (127.0.0.1:39031)\n",
      "Traceback (most recent call last):\n",
      "  File \"/opt/conda/lib/python3.7/site-packages/IPython/core/interactiveshell.py\", line 3331, in run_code\n",
      "    exec(code_obj, self.user_global_ns, self.user_ns)\n",
      "  File \"<ipython-input-18-12ee3fb1134d>\", line 1, in <module>\n",
      "    df_mes.show(5)\n",
      "  File \"/opt/spark/python/pyspark/sql/dataframe.py\", line 378, in show\n",
      "    print(self._jdf.showString(n, 20, vertical))\n",
      "  File \"/opt/spark/python/lib/py4j-0.10.7-src.zip/py4j/java_gateway.py\", line 1257, in __call__\n",
      "    answer, self.gateway_client, self.target_id, self.name)\n",
      "  File \"/opt/spark/python/pyspark/sql/utils.py\", line 63, in deco\n",
      "    return f(*a, **kw)\n",
      "  File \"/opt/spark/python/lib/py4j-0.10.7-src.zip/py4j/protocol.py\", line 336, in get_return_value\n",
      "    format(target_id, \".\", name))\n",
      "py4j.protocol.Py4JError: An error occurred while calling o242.showString\n",
      "\n",
      "During handling of the above exception, another exception occurred:\n",
      "\n",
      "Traceback (most recent call last):\n",
      "  File \"/opt/conda/lib/python3.7/site-packages/IPython/core/interactiveshell.py\", line 2044, in showtraceback\n",
      "    stb = value._render_traceback_()\n",
      "AttributeError: 'Py4JError' object has no attribute '_render_traceback_'\n",
      "\n",
      "During handling of the above exception, another exception occurred:\n",
      "\n",
      "Traceback (most recent call last):\n",
      "  File \"/opt/spark/python/lib/py4j-0.10.7-src.zip/py4j/java_gateway.py\", line 929, in _get_connection\n",
      "    connection = self.deque.pop()\n",
      "IndexError: pop from an empty deque\n",
      "\n",
      "During handling of the above exception, another exception occurred:\n",
      "\n",
      "Traceback (most recent call last):\n",
      "  File \"/opt/spark/python/lib/py4j-0.10.7-src.zip/py4j/java_gateway.py\", line 1067, in start\n",
      "    self.socket.connect((self.address, self.port))\n",
      "ConnectionRefusedError: [Errno 111] Connection refused\n",
      "ERROR:py4j.java_gateway:An error occurred while trying to connect to the Java server (127.0.0.1:39031)\n",
      "Traceback (most recent call last):\n",
      "  File \"/opt/conda/lib/python3.7/site-packages/IPython/core/interactiveshell.py\", line 3331, in run_code\n",
      "    exec(code_obj, self.user_global_ns, self.user_ns)\n",
      "  File \"<ipython-input-18-12ee3fb1134d>\", line 1, in <module>\n",
      "    df_mes.show(5)\n",
      "  File \"/opt/spark/python/pyspark/sql/dataframe.py\", line 378, in show\n",
      "    print(self._jdf.showString(n, 20, vertical))\n",
      "  File \"/opt/spark/python/lib/py4j-0.10.7-src.zip/py4j/java_gateway.py\", line 1257, in __call__\n",
      "    answer, self.gateway_client, self.target_id, self.name)\n",
      "  File \"/opt/spark/python/pyspark/sql/utils.py\", line 63, in deco\n",
      "    return f(*a, **kw)\n",
      "  File \"/opt/spark/python/lib/py4j-0.10.7-src.zip/py4j/protocol.py\", line 336, in get_return_value\n",
      "    format(target_id, \".\", name))\n",
      "py4j.protocol.Py4JError: An error occurred while calling o242.showString\n",
      "\n",
      "During handling of the above exception, another exception occurred:\n",
      "\n",
      "Traceback (most recent call last):\n",
      "  File \"/opt/conda/lib/python3.7/site-packages/IPython/core/interactiveshell.py\", line 2044, in showtraceback\n",
      "    stb = value._render_traceback_()\n",
      "AttributeError: 'Py4JError' object has no attribute '_render_traceback_'\n",
      "\n",
      "During handling of the above exception, another exception occurred:\n",
      "\n",
      "Traceback (most recent call last):\n",
      "  File \"/opt/spark/python/lib/py4j-0.10.7-src.zip/py4j/java_gateway.py\", line 929, in _get_connection\n",
      "    connection = self.deque.pop()\n",
      "IndexError: pop from an empty deque\n",
      "\n",
      "During handling of the above exception, another exception occurred:\n",
      "\n",
      "Traceback (most recent call last):\n",
      "  File \"/opt/spark/python/lib/py4j-0.10.7-src.zip/py4j/java_gateway.py\", line 1067, in start\n",
      "    self.socket.connect((self.address, self.port))\n",
      "ConnectionRefusedError: [Errno 111] Connection refused\n",
      "ERROR:py4j.java_gateway:An error occurred while trying to connect to the Java server (127.0.0.1:39031)\n",
      "Traceback (most recent call last):\n",
      "  File \"/opt/conda/lib/python3.7/site-packages/IPython/core/interactiveshell.py\", line 3331, in run_code\n",
      "    exec(code_obj, self.user_global_ns, self.user_ns)\n",
      "  File \"<ipython-input-18-12ee3fb1134d>\", line 1, in <module>\n",
      "    df_mes.show(5)\n",
      "  File \"/opt/spark/python/pyspark/sql/dataframe.py\", line 378, in show\n",
      "    print(self._jdf.showString(n, 20, vertical))\n",
      "  File \"/opt/spark/python/lib/py4j-0.10.7-src.zip/py4j/java_gateway.py\", line 1257, in __call__\n",
      "    answer, self.gateway_client, self.target_id, self.name)\n",
      "  File \"/opt/spark/python/pyspark/sql/utils.py\", line 63, in deco\n",
      "    return f(*a, **kw)\n",
      "  File \"/opt/spark/python/lib/py4j-0.10.7-src.zip/py4j/protocol.py\", line 336, in get_return_value\n",
      "    format(target_id, \".\", name))\n",
      "py4j.protocol.Py4JError: An error occurred while calling o242.showString\n",
      "\n",
      "During handling of the above exception, another exception occurred:\n",
      "\n",
      "Traceback (most recent call last):\n",
      "  File \"/opt/conda/lib/python3.7/site-packages/IPython/core/interactiveshell.py\", line 2044, in showtraceback\n",
      "    stb = value._render_traceback_()\n",
      "AttributeError: 'Py4JError' object has no attribute '_render_traceback_'\n",
      "\n",
      "During handling of the above exception, another exception occurred:\n",
      "\n",
      "Traceback (most recent call last):\n",
      "  File \"/opt/spark/python/lib/py4j-0.10.7-src.zip/py4j/java_gateway.py\", line 929, in _get_connection\n",
      "    connection = self.deque.pop()\n",
      "IndexError: pop from an empty deque\n",
      "\n",
      "During handling of the above exception, another exception occurred:\n",
      "\n",
      "Traceback (most recent call last):\n",
      "  File \"/opt/spark/python/lib/py4j-0.10.7-src.zip/py4j/java_gateway.py\", line 1067, in start\n",
      "    self.socket.connect((self.address, self.port))\n",
      "ConnectionRefusedError: [Errno 111] Connection refused\n",
      "ERROR:py4j.java_gateway:An error occurred while trying to connect to the Java server (127.0.0.1:39031)\n",
      "Traceback (most recent call last):\n",
      "  File \"/opt/conda/lib/python3.7/site-packages/IPython/core/interactiveshell.py\", line 3331, in run_code\n",
      "    exec(code_obj, self.user_global_ns, self.user_ns)\n",
      "  File \"<ipython-input-18-12ee3fb1134d>\", line 1, in <module>\n",
      "    df_mes.show(5)\n",
      "  File \"/opt/spark/python/pyspark/sql/dataframe.py\", line 378, in show\n",
      "    print(self._jdf.showString(n, 20, vertical))\n",
      "  File \"/opt/spark/python/lib/py4j-0.10.7-src.zip/py4j/java_gateway.py\", line 1257, in __call__\n",
      "    answer, self.gateway_client, self.target_id, self.name)\n",
      "  File \"/opt/spark/python/pyspark/sql/utils.py\", line 63, in deco\n",
      "    return f(*a, **kw)\n",
      "  File \"/opt/spark/python/lib/py4j-0.10.7-src.zip/py4j/protocol.py\", line 336, in get_return_value\n",
      "    format(target_id, \".\", name))\n",
      "py4j.protocol.Py4JError: An error occurred while calling o242.showString\n",
      "\n",
      "During handling of the above exception, another exception occurred:\n",
      "\n",
      "Traceback (most recent call last):\n",
      "  File \"/opt/conda/lib/python3.7/site-packages/IPython/core/interactiveshell.py\", line 2044, in showtraceback\n",
      "    stb = value._render_traceback_()\n",
      "AttributeError: 'Py4JError' object has no attribute '_render_traceback_'\n",
      "\n",
      "During handling of the above exception, another exception occurred:\n",
      "\n",
      "Traceback (most recent call last):\n",
      "  File \"/opt/spark/python/lib/py4j-0.10.7-src.zip/py4j/java_gateway.py\", line 929, in _get_connection\n",
      "    connection = self.deque.pop()\n",
      "IndexError: pop from an empty deque\n",
      "\n",
      "During handling of the above exception, another exception occurred:\n",
      "\n",
      "Traceback (most recent call last):\n",
      "  File \"/opt/spark/python/lib/py4j-0.10.7-src.zip/py4j/java_gateway.py\", line 1067, in start\n",
      "    self.socket.connect((self.address, self.port))\n",
      "ConnectionRefusedError: [Errno 111] Connection refused\n"
     ]
    },
    {
     "name": "stderr",
     "output_type": "stream",
     "text": [
      "ERROR:py4j.java_gateway:An error occurred while trying to connect to the Java server (127.0.0.1:39031)\n",
      "Traceback (most recent call last):\n",
      "  File \"/opt/conda/lib/python3.7/site-packages/IPython/core/interactiveshell.py\", line 3331, in run_code\n",
      "    exec(code_obj, self.user_global_ns, self.user_ns)\n",
      "  File \"<ipython-input-18-12ee3fb1134d>\", line 1, in <module>\n",
      "    df_mes.show(5)\n",
      "  File \"/opt/spark/python/pyspark/sql/dataframe.py\", line 378, in show\n",
      "    print(self._jdf.showString(n, 20, vertical))\n",
      "  File \"/opt/spark/python/lib/py4j-0.10.7-src.zip/py4j/java_gateway.py\", line 1257, in __call__\n",
      "    answer, self.gateway_client, self.target_id, self.name)\n",
      "  File \"/opt/spark/python/pyspark/sql/utils.py\", line 63, in deco\n",
      "    return f(*a, **kw)\n",
      "  File \"/opt/spark/python/lib/py4j-0.10.7-src.zip/py4j/protocol.py\", line 336, in get_return_value\n",
      "    format(target_id, \".\", name))\n",
      "py4j.protocol.Py4JError: An error occurred while calling o242.showString\n",
      "\n",
      "During handling of the above exception, another exception occurred:\n",
      "\n",
      "Traceback (most recent call last):\n",
      "  File \"/opt/conda/lib/python3.7/site-packages/IPython/core/interactiveshell.py\", line 2044, in showtraceback\n",
      "    stb = value._render_traceback_()\n",
      "AttributeError: 'Py4JError' object has no attribute '_render_traceback_'\n",
      "\n",
      "During handling of the above exception, another exception occurred:\n",
      "\n",
      "Traceback (most recent call last):\n",
      "  File \"/opt/spark/python/lib/py4j-0.10.7-src.zip/py4j/java_gateway.py\", line 929, in _get_connection\n",
      "    connection = self.deque.pop()\n",
      "IndexError: pop from an empty deque\n",
      "\n",
      "During handling of the above exception, another exception occurred:\n",
      "\n",
      "Traceback (most recent call last):\n",
      "  File \"/opt/spark/python/lib/py4j-0.10.7-src.zip/py4j/java_gateway.py\", line 1067, in start\n",
      "    self.socket.connect((self.address, self.port))\n",
      "ConnectionRefusedError: [Errno 111] Connection refused\n",
      "ERROR:py4j.java_gateway:An error occurred while trying to connect to the Java server (127.0.0.1:39031)\n",
      "Traceback (most recent call last):\n",
      "  File \"/opt/conda/lib/python3.7/site-packages/IPython/core/interactiveshell.py\", line 3331, in run_code\n",
      "    exec(code_obj, self.user_global_ns, self.user_ns)\n",
      "  File \"<ipython-input-18-12ee3fb1134d>\", line 1, in <module>\n",
      "    df_mes.show(5)\n",
      "  File \"/opt/spark/python/pyspark/sql/dataframe.py\", line 378, in show\n",
      "    print(self._jdf.showString(n, 20, vertical))\n",
      "  File \"/opt/spark/python/lib/py4j-0.10.7-src.zip/py4j/java_gateway.py\", line 1257, in __call__\n",
      "    answer, self.gateway_client, self.target_id, self.name)\n",
      "  File \"/opt/spark/python/pyspark/sql/utils.py\", line 63, in deco\n",
      "    return f(*a, **kw)\n",
      "  File \"/opt/spark/python/lib/py4j-0.10.7-src.zip/py4j/protocol.py\", line 336, in get_return_value\n",
      "    format(target_id, \".\", name))\n",
      "py4j.protocol.Py4JError: An error occurred while calling o242.showString\n",
      "\n",
      "During handling of the above exception, another exception occurred:\n",
      "\n",
      "Traceback (most recent call last):\n",
      "  File \"/opt/conda/lib/python3.7/site-packages/IPython/core/interactiveshell.py\", line 2044, in showtraceback\n",
      "    stb = value._render_traceback_()\n",
      "AttributeError: 'Py4JError' object has no attribute '_render_traceback_'\n",
      "\n",
      "During handling of the above exception, another exception occurred:\n",
      "\n",
      "Traceback (most recent call last):\n",
      "  File \"/opt/spark/python/lib/py4j-0.10.7-src.zip/py4j/java_gateway.py\", line 929, in _get_connection\n",
      "    connection = self.deque.pop()\n",
      "IndexError: pop from an empty deque\n",
      "\n",
      "During handling of the above exception, another exception occurred:\n",
      "\n",
      "Traceback (most recent call last):\n",
      "  File \"/opt/spark/python/lib/py4j-0.10.7-src.zip/py4j/java_gateway.py\", line 1067, in start\n",
      "    self.socket.connect((self.address, self.port))\n",
      "ConnectionRefusedError: [Errno 111] Connection refused\n",
      "ERROR:py4j.java_gateway:An error occurred while trying to connect to the Java server (127.0.0.1:39031)\n",
      "Traceback (most recent call last):\n",
      "  File \"/opt/conda/lib/python3.7/site-packages/IPython/core/interactiveshell.py\", line 3331, in run_code\n",
      "    exec(code_obj, self.user_global_ns, self.user_ns)\n",
      "  File \"<ipython-input-18-12ee3fb1134d>\", line 1, in <module>\n",
      "    df_mes.show(5)\n",
      "  File \"/opt/spark/python/pyspark/sql/dataframe.py\", line 378, in show\n",
      "    print(self._jdf.showString(n, 20, vertical))\n",
      "  File \"/opt/spark/python/lib/py4j-0.10.7-src.zip/py4j/java_gateway.py\", line 1257, in __call__\n",
      "    answer, self.gateway_client, self.target_id, self.name)\n",
      "  File \"/opt/spark/python/pyspark/sql/utils.py\", line 63, in deco\n",
      "    return f(*a, **kw)\n",
      "  File \"/opt/spark/python/lib/py4j-0.10.7-src.zip/py4j/protocol.py\", line 336, in get_return_value\n",
      "    format(target_id, \".\", name))\n",
      "py4j.protocol.Py4JError: An error occurred while calling o242.showString\n",
      "\n",
      "During handling of the above exception, another exception occurred:\n",
      "\n",
      "Traceback (most recent call last):\n",
      "  File \"/opt/conda/lib/python3.7/site-packages/IPython/core/interactiveshell.py\", line 2044, in showtraceback\n",
      "    stb = value._render_traceback_()\n",
      "AttributeError: 'Py4JError' object has no attribute '_render_traceback_'\n",
      "\n",
      "During handling of the above exception, another exception occurred:\n",
      "\n",
      "Traceback (most recent call last):\n",
      "  File \"/opt/spark/python/lib/py4j-0.10.7-src.zip/py4j/java_gateway.py\", line 929, in _get_connection\n",
      "    connection = self.deque.pop()\n",
      "IndexError: pop from an empty deque\n",
      "\n",
      "During handling of the above exception, another exception occurred:\n",
      "\n",
      "Traceback (most recent call last):\n",
      "  File \"/opt/spark/python/lib/py4j-0.10.7-src.zip/py4j/java_gateway.py\", line 1067, in start\n",
      "    self.socket.connect((self.address, self.port))\n",
      "ConnectionRefusedError: [Errno 111] Connection refused\n",
      "ERROR:py4j.java_gateway:An error occurred while trying to connect to the Java server (127.0.0.1:39031)\n",
      "Traceback (most recent call last):\n",
      "  File \"/opt/conda/lib/python3.7/site-packages/IPython/core/interactiveshell.py\", line 3331, in run_code\n",
      "    exec(code_obj, self.user_global_ns, self.user_ns)\n",
      "  File \"<ipython-input-18-12ee3fb1134d>\", line 1, in <module>\n",
      "    df_mes.show(5)\n",
      "  File \"/opt/spark/python/pyspark/sql/dataframe.py\", line 378, in show\n",
      "    print(self._jdf.showString(n, 20, vertical))\n",
      "  File \"/opt/spark/python/lib/py4j-0.10.7-src.zip/py4j/java_gateway.py\", line 1257, in __call__\n",
      "    answer, self.gateway_client, self.target_id, self.name)\n",
      "  File \"/opt/spark/python/pyspark/sql/utils.py\", line 63, in deco\n",
      "    return f(*a, **kw)\n",
      "  File \"/opt/spark/python/lib/py4j-0.10.7-src.zip/py4j/protocol.py\", line 336, in get_return_value\n",
      "    format(target_id, \".\", name))\n",
      "py4j.protocol.Py4JError: An error occurred while calling o242.showString\n",
      "\n",
      "During handling of the above exception, another exception occurred:\n",
      "\n",
      "Traceback (most recent call last):\n",
      "  File \"/opt/conda/lib/python3.7/site-packages/IPython/core/interactiveshell.py\", line 2044, in showtraceback\n",
      "    stb = value._render_traceback_()\n",
      "AttributeError: 'Py4JError' object has no attribute '_render_traceback_'\n",
      "\n",
      "During handling of the above exception, another exception occurred:\n",
      "\n",
      "Traceback (most recent call last):\n",
      "  File \"/opt/spark/python/lib/py4j-0.10.7-src.zip/py4j/java_gateway.py\", line 929, in _get_connection\n",
      "    connection = self.deque.pop()\n",
      "IndexError: pop from an empty deque\n",
      "\n",
      "During handling of the above exception, another exception occurred:\n",
      "\n",
      "Traceback (most recent call last):\n",
      "  File \"/opt/spark/python/lib/py4j-0.10.7-src.zip/py4j/java_gateway.py\", line 1067, in start\n",
      "    self.socket.connect((self.address, self.port))\n",
      "ConnectionRefusedError: [Errno 111] Connection refused\n",
      "ERROR:py4j.java_gateway:An error occurred while trying to connect to the Java server (127.0.0.1:39031)\n",
      "Traceback (most recent call last):\n",
      "  File \"/opt/conda/lib/python3.7/site-packages/IPython/core/interactiveshell.py\", line 3331, in run_code\n",
      "    exec(code_obj, self.user_global_ns, self.user_ns)\n",
      "  File \"<ipython-input-18-12ee3fb1134d>\", line 1, in <module>\n",
      "    df_mes.show(5)\n",
      "  File \"/opt/spark/python/pyspark/sql/dataframe.py\", line 378, in show\n",
      "    print(self._jdf.showString(n, 20, vertical))\n",
      "  File \"/opt/spark/python/lib/py4j-0.10.7-src.zip/py4j/java_gateway.py\", line 1257, in __call__\n",
      "    answer, self.gateway_client, self.target_id, self.name)\n",
      "  File \"/opt/spark/python/pyspark/sql/utils.py\", line 63, in deco\n",
      "    return f(*a, **kw)\n",
      "  File \"/opt/spark/python/lib/py4j-0.10.7-src.zip/py4j/protocol.py\", line 336, in get_return_value\n",
      "    format(target_id, \".\", name))\n",
      "py4j.protocol.Py4JError: An error occurred while calling o242.showString\n",
      "\n",
      "During handling of the above exception, another exception occurred:\n",
      "\n",
      "Traceback (most recent call last):\n",
      "  File \"/opt/conda/lib/python3.7/site-packages/IPython/core/interactiveshell.py\", line 2044, in showtraceback\n",
      "    stb = value._render_traceback_()\n",
      "AttributeError: 'Py4JError' object has no attribute '_render_traceback_'\n",
      "\n",
      "During handling of the above exception, another exception occurred:\n",
      "\n",
      "Traceback (most recent call last):\n",
      "  File \"/opt/spark/python/lib/py4j-0.10.7-src.zip/py4j/java_gateway.py\", line 929, in _get_connection\n",
      "    connection = self.deque.pop()\n",
      "IndexError: pop from an empty deque\n",
      "\n",
      "During handling of the above exception, another exception occurred:\n",
      "\n",
      "Traceback (most recent call last):\n",
      "  File \"/opt/spark/python/lib/py4j-0.10.7-src.zip/py4j/java_gateway.py\", line 1067, in start\n",
      "    self.socket.connect((self.address, self.port))\n",
      "ConnectionRefusedError: [Errno 111] Connection refused\n"
     ]
    },
    {
     "name": "stderr",
     "output_type": "stream",
     "text": [
      "ERROR:py4j.java_gateway:An error occurred while trying to connect to the Java server (127.0.0.1:39031)\n",
      "Traceback (most recent call last):\n",
      "  File \"/opt/conda/lib/python3.7/site-packages/IPython/core/interactiveshell.py\", line 3331, in run_code\n",
      "    exec(code_obj, self.user_global_ns, self.user_ns)\n",
      "  File \"<ipython-input-18-12ee3fb1134d>\", line 1, in <module>\n",
      "    df_mes.show(5)\n",
      "  File \"/opt/spark/python/pyspark/sql/dataframe.py\", line 378, in show\n",
      "    print(self._jdf.showString(n, 20, vertical))\n",
      "  File \"/opt/spark/python/lib/py4j-0.10.7-src.zip/py4j/java_gateway.py\", line 1257, in __call__\n",
      "    answer, self.gateway_client, self.target_id, self.name)\n",
      "  File \"/opt/spark/python/pyspark/sql/utils.py\", line 63, in deco\n",
      "    return f(*a, **kw)\n",
      "  File \"/opt/spark/python/lib/py4j-0.10.7-src.zip/py4j/protocol.py\", line 336, in get_return_value\n",
      "    format(target_id, \".\", name))\n",
      "py4j.protocol.Py4JError: An error occurred while calling o242.showString\n",
      "\n",
      "During handling of the above exception, another exception occurred:\n",
      "\n",
      "Traceback (most recent call last):\n",
      "  File \"/opt/conda/lib/python3.7/site-packages/IPython/core/interactiveshell.py\", line 2044, in showtraceback\n",
      "    stb = value._render_traceback_()\n",
      "AttributeError: 'Py4JError' object has no attribute '_render_traceback_'\n",
      "\n",
      "During handling of the above exception, another exception occurred:\n",
      "\n",
      "Traceback (most recent call last):\n",
      "  File \"/opt/spark/python/lib/py4j-0.10.7-src.zip/py4j/java_gateway.py\", line 929, in _get_connection\n",
      "    connection = self.deque.pop()\n",
      "IndexError: pop from an empty deque\n",
      "\n",
      "During handling of the above exception, another exception occurred:\n",
      "\n",
      "Traceback (most recent call last):\n",
      "  File \"/opt/spark/python/lib/py4j-0.10.7-src.zip/py4j/java_gateway.py\", line 1067, in start\n",
      "    self.socket.connect((self.address, self.port))\n",
      "ConnectionRefusedError: [Errno 111] Connection refused\n",
      "ERROR:py4j.java_gateway:An error occurred while trying to connect to the Java server (127.0.0.1:39031)\n",
      "Traceback (most recent call last):\n",
      "  File \"/opt/conda/lib/python3.7/site-packages/IPython/core/interactiveshell.py\", line 3331, in run_code\n",
      "    exec(code_obj, self.user_global_ns, self.user_ns)\n",
      "  File \"<ipython-input-18-12ee3fb1134d>\", line 1, in <module>\n",
      "    df_mes.show(5)\n",
      "  File \"/opt/spark/python/pyspark/sql/dataframe.py\", line 378, in show\n",
      "    print(self._jdf.showString(n, 20, vertical))\n",
      "  File \"/opt/spark/python/lib/py4j-0.10.7-src.zip/py4j/java_gateway.py\", line 1257, in __call__\n",
      "    answer, self.gateway_client, self.target_id, self.name)\n",
      "  File \"/opt/spark/python/pyspark/sql/utils.py\", line 63, in deco\n",
      "    return f(*a, **kw)\n",
      "  File \"/opt/spark/python/lib/py4j-0.10.7-src.zip/py4j/protocol.py\", line 336, in get_return_value\n",
      "    format(target_id, \".\", name))\n",
      "py4j.protocol.Py4JError: An error occurred while calling o242.showString\n",
      "\n",
      "During handling of the above exception, another exception occurred:\n",
      "\n",
      "Traceback (most recent call last):\n",
      "  File \"/opt/conda/lib/python3.7/site-packages/IPython/core/interactiveshell.py\", line 2044, in showtraceback\n",
      "    stb = value._render_traceback_()\n",
      "AttributeError: 'Py4JError' object has no attribute '_render_traceback_'\n",
      "\n",
      "During handling of the above exception, another exception occurred:\n",
      "\n",
      "Traceback (most recent call last):\n",
      "  File \"/opt/spark/python/lib/py4j-0.10.7-src.zip/py4j/java_gateway.py\", line 929, in _get_connection\n",
      "    connection = self.deque.pop()\n",
      "IndexError: pop from an empty deque\n",
      "\n",
      "During handling of the above exception, another exception occurred:\n",
      "\n",
      "Traceback (most recent call last):\n",
      "  File \"/opt/spark/python/lib/py4j-0.10.7-src.zip/py4j/java_gateway.py\", line 1067, in start\n",
      "    self.socket.connect((self.address, self.port))\n",
      "ConnectionRefusedError: [Errno 111] Connection refused\n",
      "ERROR:py4j.java_gateway:An error occurred while trying to connect to the Java server (127.0.0.1:39031)\n",
      "Traceback (most recent call last):\n",
      "  File \"/opt/conda/lib/python3.7/site-packages/IPython/core/interactiveshell.py\", line 3331, in run_code\n",
      "    exec(code_obj, self.user_global_ns, self.user_ns)\n",
      "  File \"<ipython-input-18-12ee3fb1134d>\", line 1, in <module>\n",
      "    df_mes.show(5)\n",
      "  File \"/opt/spark/python/pyspark/sql/dataframe.py\", line 378, in show\n",
      "    print(self._jdf.showString(n, 20, vertical))\n",
      "  File \"/opt/spark/python/lib/py4j-0.10.7-src.zip/py4j/java_gateway.py\", line 1257, in __call__\n",
      "    answer, self.gateway_client, self.target_id, self.name)\n",
      "  File \"/opt/spark/python/pyspark/sql/utils.py\", line 63, in deco\n",
      "    return f(*a, **kw)\n",
      "  File \"/opt/spark/python/lib/py4j-0.10.7-src.zip/py4j/protocol.py\", line 336, in get_return_value\n",
      "    format(target_id, \".\", name))\n",
      "py4j.protocol.Py4JError: An error occurred while calling o242.showString\n",
      "\n",
      "During handling of the above exception, another exception occurred:\n",
      "\n",
      "Traceback (most recent call last):\n",
      "  File \"/opt/conda/lib/python3.7/site-packages/IPython/core/interactiveshell.py\", line 2044, in showtraceback\n",
      "    stb = value._render_traceback_()\n",
      "AttributeError: 'Py4JError' object has no attribute '_render_traceback_'\n",
      "\n",
      "During handling of the above exception, another exception occurred:\n",
      "\n",
      "Traceback (most recent call last):\n",
      "  File \"/opt/spark/python/lib/py4j-0.10.7-src.zip/py4j/java_gateway.py\", line 929, in _get_connection\n",
      "    connection = self.deque.pop()\n",
      "IndexError: pop from an empty deque\n",
      "\n",
      "During handling of the above exception, another exception occurred:\n",
      "\n",
      "Traceback (most recent call last):\n",
      "  File \"/opt/spark/python/lib/py4j-0.10.7-src.zip/py4j/java_gateway.py\", line 1067, in start\n",
      "    self.socket.connect((self.address, self.port))\n",
      "ConnectionRefusedError: [Errno 111] Connection refused\n",
      "ERROR:py4j.java_gateway:An error occurred while trying to connect to the Java server (127.0.0.1:39031)\n",
      "Traceback (most recent call last):\n",
      "  File \"/opt/conda/lib/python3.7/site-packages/IPython/core/interactiveshell.py\", line 3331, in run_code\n",
      "    exec(code_obj, self.user_global_ns, self.user_ns)\n",
      "  File \"<ipython-input-18-12ee3fb1134d>\", line 1, in <module>\n",
      "    df_mes.show(5)\n",
      "  File \"/opt/spark/python/pyspark/sql/dataframe.py\", line 378, in show\n",
      "    print(self._jdf.showString(n, 20, vertical))\n",
      "  File \"/opt/spark/python/lib/py4j-0.10.7-src.zip/py4j/java_gateway.py\", line 1257, in __call__\n",
      "    answer, self.gateway_client, self.target_id, self.name)\n",
      "  File \"/opt/spark/python/pyspark/sql/utils.py\", line 63, in deco\n",
      "    return f(*a, **kw)\n",
      "  File \"/opt/spark/python/lib/py4j-0.10.7-src.zip/py4j/protocol.py\", line 336, in get_return_value\n",
      "    format(target_id, \".\", name))\n",
      "py4j.protocol.Py4JError: An error occurred while calling o242.showString\n",
      "\n",
      "During handling of the above exception, another exception occurred:\n",
      "\n",
      "Traceback (most recent call last):\n",
      "  File \"/opt/conda/lib/python3.7/site-packages/IPython/core/interactiveshell.py\", line 2044, in showtraceback\n",
      "    stb = value._render_traceback_()\n",
      "AttributeError: 'Py4JError' object has no attribute '_render_traceback_'\n",
      "\n",
      "During handling of the above exception, another exception occurred:\n",
      "\n",
      "Traceback (most recent call last):\n",
      "  File \"/opt/spark/python/lib/py4j-0.10.7-src.zip/py4j/java_gateway.py\", line 929, in _get_connection\n",
      "    connection = self.deque.pop()\n",
      "IndexError: pop from an empty deque\n",
      "\n",
      "During handling of the above exception, another exception occurred:\n",
      "\n",
      "Traceback (most recent call last):\n",
      "  File \"/opt/spark/python/lib/py4j-0.10.7-src.zip/py4j/java_gateway.py\", line 1067, in start\n",
      "    self.socket.connect((self.address, self.port))\n",
      "ConnectionRefusedError: [Errno 111] Connection refused\n",
      "ERROR:py4j.java_gateway:An error occurred while trying to connect to the Java server (127.0.0.1:39031)\n",
      "Traceback (most recent call last):\n",
      "  File \"/opt/conda/lib/python3.7/site-packages/IPython/core/interactiveshell.py\", line 3331, in run_code\n",
      "    exec(code_obj, self.user_global_ns, self.user_ns)\n",
      "  File \"<ipython-input-18-12ee3fb1134d>\", line 1, in <module>\n",
      "    df_mes.show(5)\n",
      "  File \"/opt/spark/python/pyspark/sql/dataframe.py\", line 378, in show\n",
      "    print(self._jdf.showString(n, 20, vertical))\n",
      "  File \"/opt/spark/python/lib/py4j-0.10.7-src.zip/py4j/java_gateway.py\", line 1257, in __call__\n",
      "    answer, self.gateway_client, self.target_id, self.name)\n",
      "  File \"/opt/spark/python/pyspark/sql/utils.py\", line 63, in deco\n",
      "    return f(*a, **kw)\n",
      "  File \"/opt/spark/python/lib/py4j-0.10.7-src.zip/py4j/protocol.py\", line 336, in get_return_value\n",
      "    format(target_id, \".\", name))\n",
      "py4j.protocol.Py4JError: An error occurred while calling o242.showString\n",
      "\n",
      "During handling of the above exception, another exception occurred:\n",
      "\n",
      "Traceback (most recent call last):\n",
      "  File \"/opt/conda/lib/python3.7/site-packages/IPython/core/interactiveshell.py\", line 2044, in showtraceback\n",
      "    stb = value._render_traceback_()\n",
      "AttributeError: 'Py4JError' object has no attribute '_render_traceback_'\n",
      "\n",
      "During handling of the above exception, another exception occurred:\n",
      "\n",
      "Traceback (most recent call last):\n",
      "  File \"/opt/spark/python/lib/py4j-0.10.7-src.zip/py4j/java_gateway.py\", line 929, in _get_connection\n",
      "    connection = self.deque.pop()\n",
      "IndexError: pop from an empty deque\n",
      "\n",
      "During handling of the above exception, another exception occurred:\n",
      "\n",
      "Traceback (most recent call last):\n",
      "  File \"/opt/spark/python/lib/py4j-0.10.7-src.zip/py4j/java_gateway.py\", line 1067, in start\n",
      "    self.socket.connect((self.address, self.port))\n",
      "ConnectionRefusedError: [Errno 111] Connection refused\n"
     ]
    },
    {
     "name": "stderr",
     "output_type": "stream",
     "text": [
      "ERROR:py4j.java_gateway:An error occurred while trying to connect to the Java server (127.0.0.1:39031)\n",
      "Traceback (most recent call last):\n",
      "  File \"/opt/conda/lib/python3.7/site-packages/IPython/core/interactiveshell.py\", line 3331, in run_code\n",
      "    exec(code_obj, self.user_global_ns, self.user_ns)\n",
      "  File \"<ipython-input-18-12ee3fb1134d>\", line 1, in <module>\n",
      "    df_mes.show(5)\n",
      "  File \"/opt/spark/python/pyspark/sql/dataframe.py\", line 378, in show\n",
      "    print(self._jdf.showString(n, 20, vertical))\n",
      "  File \"/opt/spark/python/lib/py4j-0.10.7-src.zip/py4j/java_gateway.py\", line 1257, in __call__\n",
      "    answer, self.gateway_client, self.target_id, self.name)\n",
      "  File \"/opt/spark/python/pyspark/sql/utils.py\", line 63, in deco\n",
      "    return f(*a, **kw)\n",
      "  File \"/opt/spark/python/lib/py4j-0.10.7-src.zip/py4j/protocol.py\", line 336, in get_return_value\n",
      "    format(target_id, \".\", name))\n",
      "py4j.protocol.Py4JError: An error occurred while calling o242.showString\n",
      "\n",
      "During handling of the above exception, another exception occurred:\n",
      "\n",
      "Traceback (most recent call last):\n",
      "  File \"/opt/conda/lib/python3.7/site-packages/IPython/core/interactiveshell.py\", line 2044, in showtraceback\n",
      "    stb = value._render_traceback_()\n",
      "AttributeError: 'Py4JError' object has no attribute '_render_traceback_'\n",
      "\n",
      "During handling of the above exception, another exception occurred:\n",
      "\n",
      "Traceback (most recent call last):\n",
      "  File \"/opt/spark/python/lib/py4j-0.10.7-src.zip/py4j/java_gateway.py\", line 929, in _get_connection\n",
      "    connection = self.deque.pop()\n",
      "IndexError: pop from an empty deque\n",
      "\n",
      "During handling of the above exception, another exception occurred:\n",
      "\n",
      "Traceback (most recent call last):\n",
      "  File \"/opt/spark/python/lib/py4j-0.10.7-src.zip/py4j/java_gateway.py\", line 1067, in start\n",
      "    self.socket.connect((self.address, self.port))\n",
      "ConnectionRefusedError: [Errno 111] Connection refused\n",
      "ERROR:py4j.java_gateway:An error occurred while trying to connect to the Java server (127.0.0.1:39031)\n",
      "Traceback (most recent call last):\n",
      "  File \"/opt/conda/lib/python3.7/site-packages/IPython/core/interactiveshell.py\", line 3331, in run_code\n",
      "    exec(code_obj, self.user_global_ns, self.user_ns)\n",
      "  File \"<ipython-input-18-12ee3fb1134d>\", line 1, in <module>\n",
      "    df_mes.show(5)\n",
      "  File \"/opt/spark/python/pyspark/sql/dataframe.py\", line 378, in show\n",
      "    print(self._jdf.showString(n, 20, vertical))\n",
      "  File \"/opt/spark/python/lib/py4j-0.10.7-src.zip/py4j/java_gateway.py\", line 1257, in __call__\n",
      "    answer, self.gateway_client, self.target_id, self.name)\n",
      "  File \"/opt/spark/python/pyspark/sql/utils.py\", line 63, in deco\n",
      "    return f(*a, **kw)\n",
      "  File \"/opt/spark/python/lib/py4j-0.10.7-src.zip/py4j/protocol.py\", line 336, in get_return_value\n",
      "    format(target_id, \".\", name))\n",
      "py4j.protocol.Py4JError: An error occurred while calling o242.showString\n",
      "\n",
      "During handling of the above exception, another exception occurred:\n",
      "\n",
      "Traceback (most recent call last):\n",
      "  File \"/opt/conda/lib/python3.7/site-packages/IPython/core/interactiveshell.py\", line 2044, in showtraceback\n",
      "    stb = value._render_traceback_()\n",
      "AttributeError: 'Py4JError' object has no attribute '_render_traceback_'\n",
      "\n",
      "During handling of the above exception, another exception occurred:\n",
      "\n",
      "Traceback (most recent call last):\n",
      "  File \"/opt/spark/python/lib/py4j-0.10.7-src.zip/py4j/java_gateway.py\", line 929, in _get_connection\n",
      "    connection = self.deque.pop()\n",
      "IndexError: pop from an empty deque\n",
      "\n",
      "During handling of the above exception, another exception occurred:\n",
      "\n",
      "Traceback (most recent call last):\n",
      "  File \"/opt/spark/python/lib/py4j-0.10.7-src.zip/py4j/java_gateway.py\", line 1067, in start\n",
      "    self.socket.connect((self.address, self.port))\n",
      "ConnectionRefusedError: [Errno 111] Connection refused\n",
      "ERROR:py4j.java_gateway:An error occurred while trying to connect to the Java server (127.0.0.1:39031)\n",
      "Traceback (most recent call last):\n",
      "  File \"/opt/conda/lib/python3.7/site-packages/IPython/core/interactiveshell.py\", line 3331, in run_code\n",
      "    exec(code_obj, self.user_global_ns, self.user_ns)\n",
      "  File \"<ipython-input-18-12ee3fb1134d>\", line 1, in <module>\n",
      "    df_mes.show(5)\n",
      "  File \"/opt/spark/python/pyspark/sql/dataframe.py\", line 378, in show\n",
      "    print(self._jdf.showString(n, 20, vertical))\n",
      "  File \"/opt/spark/python/lib/py4j-0.10.7-src.zip/py4j/java_gateway.py\", line 1257, in __call__\n",
      "    answer, self.gateway_client, self.target_id, self.name)\n",
      "  File \"/opt/spark/python/pyspark/sql/utils.py\", line 63, in deco\n",
      "    return f(*a, **kw)\n",
      "  File \"/opt/spark/python/lib/py4j-0.10.7-src.zip/py4j/protocol.py\", line 336, in get_return_value\n",
      "    format(target_id, \".\", name))\n",
      "py4j.protocol.Py4JError: An error occurred while calling o242.showString\n",
      "\n",
      "During handling of the above exception, another exception occurred:\n",
      "\n",
      "Traceback (most recent call last):\n",
      "  File \"/opt/conda/lib/python3.7/site-packages/IPython/core/interactiveshell.py\", line 2044, in showtraceback\n",
      "    stb = value._render_traceback_()\n",
      "AttributeError: 'Py4JError' object has no attribute '_render_traceback_'\n",
      "\n",
      "During handling of the above exception, another exception occurred:\n",
      "\n",
      "Traceback (most recent call last):\n",
      "  File \"/opt/spark/python/lib/py4j-0.10.7-src.zip/py4j/java_gateway.py\", line 929, in _get_connection\n",
      "    connection = self.deque.pop()\n",
      "IndexError: pop from an empty deque\n",
      "\n",
      "During handling of the above exception, another exception occurred:\n",
      "\n",
      "Traceback (most recent call last):\n",
      "  File \"/opt/spark/python/lib/py4j-0.10.7-src.zip/py4j/java_gateway.py\", line 1067, in start\n",
      "    self.socket.connect((self.address, self.port))\n",
      "ConnectionRefusedError: [Errno 111] Connection refused\n",
      "ERROR:py4j.java_gateway:An error occurred while trying to connect to the Java server (127.0.0.1:39031)\n",
      "Traceback (most recent call last):\n",
      "  File \"/opt/conda/lib/python3.7/site-packages/IPython/core/interactiveshell.py\", line 3331, in run_code\n",
      "    exec(code_obj, self.user_global_ns, self.user_ns)\n",
      "  File \"<ipython-input-18-12ee3fb1134d>\", line 1, in <module>\n",
      "    df_mes.show(5)\n",
      "  File \"/opt/spark/python/pyspark/sql/dataframe.py\", line 378, in show\n",
      "    print(self._jdf.showString(n, 20, vertical))\n",
      "  File \"/opt/spark/python/lib/py4j-0.10.7-src.zip/py4j/java_gateway.py\", line 1257, in __call__\n",
      "    answer, self.gateway_client, self.target_id, self.name)\n",
      "  File \"/opt/spark/python/pyspark/sql/utils.py\", line 63, in deco\n",
      "    return f(*a, **kw)\n",
      "  File \"/opt/spark/python/lib/py4j-0.10.7-src.zip/py4j/protocol.py\", line 336, in get_return_value\n",
      "    format(target_id, \".\", name))\n",
      "py4j.protocol.Py4JError: An error occurred while calling o242.showString\n",
      "\n",
      "During handling of the above exception, another exception occurred:\n",
      "\n",
      "Traceback (most recent call last):\n",
      "  File \"/opt/conda/lib/python3.7/site-packages/IPython/core/interactiveshell.py\", line 2044, in showtraceback\n",
      "    stb = value._render_traceback_()\n",
      "AttributeError: 'Py4JError' object has no attribute '_render_traceback_'\n",
      "\n",
      "During handling of the above exception, another exception occurred:\n",
      "\n",
      "Traceback (most recent call last):\n",
      "  File \"/opt/spark/python/lib/py4j-0.10.7-src.zip/py4j/java_gateway.py\", line 929, in _get_connection\n",
      "    connection = self.deque.pop()\n",
      "IndexError: pop from an empty deque\n",
      "\n",
      "During handling of the above exception, another exception occurred:\n",
      "\n",
      "Traceback (most recent call last):\n",
      "  File \"/opt/spark/python/lib/py4j-0.10.7-src.zip/py4j/java_gateway.py\", line 1067, in start\n",
      "    self.socket.connect((self.address, self.port))\n",
      "ConnectionRefusedError: [Errno 111] Connection refused\n",
      "ERROR:py4j.java_gateway:An error occurred while trying to connect to the Java server (127.0.0.1:39031)\n",
      "Traceback (most recent call last):\n",
      "  File \"/opt/conda/lib/python3.7/site-packages/IPython/core/interactiveshell.py\", line 3331, in run_code\n",
      "    exec(code_obj, self.user_global_ns, self.user_ns)\n",
      "  File \"<ipython-input-18-12ee3fb1134d>\", line 1, in <module>\n",
      "    df_mes.show(5)\n",
      "  File \"/opt/spark/python/pyspark/sql/dataframe.py\", line 378, in show\n",
      "    print(self._jdf.showString(n, 20, vertical))\n",
      "  File \"/opt/spark/python/lib/py4j-0.10.7-src.zip/py4j/java_gateway.py\", line 1257, in __call__\n",
      "    answer, self.gateway_client, self.target_id, self.name)\n",
      "  File \"/opt/spark/python/pyspark/sql/utils.py\", line 63, in deco\n",
      "    return f(*a, **kw)\n",
      "  File \"/opt/spark/python/lib/py4j-0.10.7-src.zip/py4j/protocol.py\", line 336, in get_return_value\n",
      "    format(target_id, \".\", name))\n",
      "py4j.protocol.Py4JError: An error occurred while calling o242.showString\n",
      "\n",
      "During handling of the above exception, another exception occurred:\n",
      "\n",
      "Traceback (most recent call last):\n",
      "  File \"/opt/conda/lib/python3.7/site-packages/IPython/core/interactiveshell.py\", line 2044, in showtraceback\n",
      "    stb = value._render_traceback_()\n",
      "AttributeError: 'Py4JError' object has no attribute '_render_traceback_'\n",
      "\n",
      "During handling of the above exception, another exception occurred:\n",
      "\n",
      "Traceback (most recent call last):\n",
      "  File \"/opt/spark/python/lib/py4j-0.10.7-src.zip/py4j/java_gateway.py\", line 929, in _get_connection\n",
      "    connection = self.deque.pop()\n",
      "IndexError: pop from an empty deque\n",
      "\n",
      "During handling of the above exception, another exception occurred:\n",
      "\n",
      "Traceback (most recent call last):\n",
      "  File \"/opt/spark/python/lib/py4j-0.10.7-src.zip/py4j/java_gateway.py\", line 1067, in start\n",
      "    self.socket.connect((self.address, self.port))\n",
      "ConnectionRefusedError: [Errno 111] Connection refused\n"
     ]
    },
    {
     "name": "stderr",
     "output_type": "stream",
     "text": [
      "ERROR:py4j.java_gateway:An error occurred while trying to connect to the Java server (127.0.0.1:39031)\n",
      "Traceback (most recent call last):\n",
      "  File \"/opt/conda/lib/python3.7/site-packages/IPython/core/interactiveshell.py\", line 3331, in run_code\n",
      "    exec(code_obj, self.user_global_ns, self.user_ns)\n",
      "  File \"<ipython-input-18-12ee3fb1134d>\", line 1, in <module>\n",
      "    df_mes.show(5)\n",
      "  File \"/opt/spark/python/pyspark/sql/dataframe.py\", line 378, in show\n",
      "    print(self._jdf.showString(n, 20, vertical))\n",
      "  File \"/opt/spark/python/lib/py4j-0.10.7-src.zip/py4j/java_gateway.py\", line 1257, in __call__\n",
      "    answer, self.gateway_client, self.target_id, self.name)\n",
      "  File \"/opt/spark/python/pyspark/sql/utils.py\", line 63, in deco\n",
      "    return f(*a, **kw)\n",
      "  File \"/opt/spark/python/lib/py4j-0.10.7-src.zip/py4j/protocol.py\", line 336, in get_return_value\n",
      "    format(target_id, \".\", name))\n",
      "py4j.protocol.Py4JError: An error occurred while calling o242.showString\n",
      "\n",
      "During handling of the above exception, another exception occurred:\n",
      "\n",
      "Traceback (most recent call last):\n",
      "  File \"/opt/conda/lib/python3.7/site-packages/IPython/core/interactiveshell.py\", line 2044, in showtraceback\n",
      "    stb = value._render_traceback_()\n",
      "AttributeError: 'Py4JError' object has no attribute '_render_traceback_'\n",
      "\n",
      "During handling of the above exception, another exception occurred:\n",
      "\n",
      "Traceback (most recent call last):\n",
      "  File \"/opt/spark/python/lib/py4j-0.10.7-src.zip/py4j/java_gateway.py\", line 929, in _get_connection\n",
      "    connection = self.deque.pop()\n",
      "IndexError: pop from an empty deque\n",
      "\n",
      "During handling of the above exception, another exception occurred:\n",
      "\n",
      "Traceback (most recent call last):\n",
      "  File \"/opt/spark/python/lib/py4j-0.10.7-src.zip/py4j/java_gateway.py\", line 1067, in start\n",
      "    self.socket.connect((self.address, self.port))\n",
      "ConnectionRefusedError: [Errno 111] Connection refused\n",
      "ERROR:py4j.java_gateway:An error occurred while trying to connect to the Java server (127.0.0.1:39031)\n",
      "Traceback (most recent call last):\n",
      "  File \"/opt/conda/lib/python3.7/site-packages/IPython/core/interactiveshell.py\", line 3331, in run_code\n",
      "    exec(code_obj, self.user_global_ns, self.user_ns)\n",
      "  File \"<ipython-input-18-12ee3fb1134d>\", line 1, in <module>\n",
      "    df_mes.show(5)\n",
      "  File \"/opt/spark/python/pyspark/sql/dataframe.py\", line 378, in show\n",
      "    print(self._jdf.showString(n, 20, vertical))\n",
      "  File \"/opt/spark/python/lib/py4j-0.10.7-src.zip/py4j/java_gateway.py\", line 1257, in __call__\n",
      "    answer, self.gateway_client, self.target_id, self.name)\n",
      "  File \"/opt/spark/python/pyspark/sql/utils.py\", line 63, in deco\n",
      "    return f(*a, **kw)\n",
      "  File \"/opt/spark/python/lib/py4j-0.10.7-src.zip/py4j/protocol.py\", line 336, in get_return_value\n",
      "    format(target_id, \".\", name))\n",
      "py4j.protocol.Py4JError: An error occurred while calling o242.showString\n",
      "\n",
      "During handling of the above exception, another exception occurred:\n",
      "\n",
      "Traceback (most recent call last):\n",
      "  File \"/opt/conda/lib/python3.7/site-packages/IPython/core/interactiveshell.py\", line 2044, in showtraceback\n",
      "    stb = value._render_traceback_()\n",
      "AttributeError: 'Py4JError' object has no attribute '_render_traceback_'\n",
      "\n",
      "During handling of the above exception, another exception occurred:\n",
      "\n",
      "Traceback (most recent call last):\n",
      "  File \"/opt/spark/python/lib/py4j-0.10.7-src.zip/py4j/java_gateway.py\", line 929, in _get_connection\n",
      "    connection = self.deque.pop()\n",
      "IndexError: pop from an empty deque\n",
      "\n",
      "During handling of the above exception, another exception occurred:\n",
      "\n",
      "Traceback (most recent call last):\n",
      "  File \"/opt/spark/python/lib/py4j-0.10.7-src.zip/py4j/java_gateway.py\", line 1067, in start\n",
      "    self.socket.connect((self.address, self.port))\n",
      "ConnectionRefusedError: [Errno 111] Connection refused\n",
      "ERROR:py4j.java_gateway:An error occurred while trying to connect to the Java server (127.0.0.1:39031)\n",
      "Traceback (most recent call last):\n",
      "  File \"/opt/conda/lib/python3.7/site-packages/IPython/core/interactiveshell.py\", line 3331, in run_code\n",
      "    exec(code_obj, self.user_global_ns, self.user_ns)\n",
      "  File \"<ipython-input-18-12ee3fb1134d>\", line 1, in <module>\n",
      "    df_mes.show(5)\n",
      "  File \"/opt/spark/python/pyspark/sql/dataframe.py\", line 378, in show\n",
      "    print(self._jdf.showString(n, 20, vertical))\n",
      "  File \"/opt/spark/python/lib/py4j-0.10.7-src.zip/py4j/java_gateway.py\", line 1257, in __call__\n",
      "    answer, self.gateway_client, self.target_id, self.name)\n",
      "  File \"/opt/spark/python/pyspark/sql/utils.py\", line 63, in deco\n",
      "    return f(*a, **kw)\n",
      "  File \"/opt/spark/python/lib/py4j-0.10.7-src.zip/py4j/protocol.py\", line 336, in get_return_value\n",
      "    format(target_id, \".\", name))\n",
      "py4j.protocol.Py4JError: An error occurred while calling o242.showString\n",
      "\n",
      "During handling of the above exception, another exception occurred:\n",
      "\n",
      "Traceback (most recent call last):\n",
      "  File \"/opt/conda/lib/python3.7/site-packages/IPython/core/interactiveshell.py\", line 2044, in showtraceback\n",
      "    stb = value._render_traceback_()\n",
      "AttributeError: 'Py4JError' object has no attribute '_render_traceback_'\n",
      "\n",
      "During handling of the above exception, another exception occurred:\n",
      "\n",
      "Traceback (most recent call last):\n",
      "  File \"/opt/spark/python/lib/py4j-0.10.7-src.zip/py4j/java_gateway.py\", line 929, in _get_connection\n",
      "    connection = self.deque.pop()\n",
      "IndexError: pop from an empty deque\n",
      "\n",
      "During handling of the above exception, another exception occurred:\n",
      "\n",
      "Traceback (most recent call last):\n",
      "  File \"/opt/spark/python/lib/py4j-0.10.7-src.zip/py4j/java_gateway.py\", line 1067, in start\n",
      "    self.socket.connect((self.address, self.port))\n",
      "ConnectionRefusedError: [Errno 111] Connection refused\n",
      "ERROR:py4j.java_gateway:An error occurred while trying to connect to the Java server (127.0.0.1:39031)\n",
      "Traceback (most recent call last):\n",
      "  File \"/opt/conda/lib/python3.7/site-packages/IPython/core/interactiveshell.py\", line 3331, in run_code\n",
      "    exec(code_obj, self.user_global_ns, self.user_ns)\n",
      "  File \"<ipython-input-18-12ee3fb1134d>\", line 1, in <module>\n",
      "    df_mes.show(5)\n",
      "  File \"/opt/spark/python/pyspark/sql/dataframe.py\", line 378, in show\n",
      "    print(self._jdf.showString(n, 20, vertical))\n",
      "  File \"/opt/spark/python/lib/py4j-0.10.7-src.zip/py4j/java_gateway.py\", line 1257, in __call__\n",
      "    answer, self.gateway_client, self.target_id, self.name)\n",
      "  File \"/opt/spark/python/pyspark/sql/utils.py\", line 63, in deco\n",
      "    return f(*a, **kw)\n",
      "  File \"/opt/spark/python/lib/py4j-0.10.7-src.zip/py4j/protocol.py\", line 336, in get_return_value\n",
      "    format(target_id, \".\", name))\n",
      "py4j.protocol.Py4JError: An error occurred while calling o242.showString\n",
      "\n",
      "During handling of the above exception, another exception occurred:\n",
      "\n",
      "Traceback (most recent call last):\n",
      "  File \"/opt/conda/lib/python3.7/site-packages/IPython/core/interactiveshell.py\", line 2044, in showtraceback\n",
      "    stb = value._render_traceback_()\n",
      "AttributeError: 'Py4JError' object has no attribute '_render_traceback_'\n",
      "\n",
      "During handling of the above exception, another exception occurred:\n",
      "\n",
      "Traceback (most recent call last):\n",
      "  File \"/opt/spark/python/lib/py4j-0.10.7-src.zip/py4j/java_gateway.py\", line 929, in _get_connection\n",
      "    connection = self.deque.pop()\n",
      "IndexError: pop from an empty deque\n",
      "\n",
      "During handling of the above exception, another exception occurred:\n",
      "\n",
      "Traceback (most recent call last):\n",
      "  File \"/opt/spark/python/lib/py4j-0.10.7-src.zip/py4j/java_gateway.py\", line 1067, in start\n",
      "    self.socket.connect((self.address, self.port))\n",
      "ConnectionRefusedError: [Errno 111] Connection refused\n",
      "ERROR:py4j.java_gateway:An error occurred while trying to connect to the Java server (127.0.0.1:39031)\n",
      "Traceback (most recent call last):\n",
      "  File \"/opt/conda/lib/python3.7/site-packages/IPython/core/interactiveshell.py\", line 3331, in run_code\n",
      "    exec(code_obj, self.user_global_ns, self.user_ns)\n",
      "  File \"<ipython-input-18-12ee3fb1134d>\", line 1, in <module>\n",
      "    df_mes.show(5)\n",
      "  File \"/opt/spark/python/pyspark/sql/dataframe.py\", line 378, in show\n",
      "    print(self._jdf.showString(n, 20, vertical))\n",
      "  File \"/opt/spark/python/lib/py4j-0.10.7-src.zip/py4j/java_gateway.py\", line 1257, in __call__\n",
      "    answer, self.gateway_client, self.target_id, self.name)\n",
      "  File \"/opt/spark/python/pyspark/sql/utils.py\", line 63, in deco\n",
      "    return f(*a, **kw)\n",
      "  File \"/opt/spark/python/lib/py4j-0.10.7-src.zip/py4j/protocol.py\", line 336, in get_return_value\n",
      "    format(target_id, \".\", name))\n",
      "py4j.protocol.Py4JError: An error occurred while calling o242.showString\n",
      "\n",
      "During handling of the above exception, another exception occurred:\n",
      "\n",
      "Traceback (most recent call last):\n",
      "  File \"/opt/conda/lib/python3.7/site-packages/IPython/core/interactiveshell.py\", line 2044, in showtraceback\n",
      "    stb = value._render_traceback_()\n",
      "AttributeError: 'Py4JError' object has no attribute '_render_traceback_'\n",
      "\n",
      "During handling of the above exception, another exception occurred:\n",
      "\n",
      "Traceback (most recent call last):\n",
      "  File \"/opt/spark/python/lib/py4j-0.10.7-src.zip/py4j/java_gateway.py\", line 929, in _get_connection\n",
      "    connection = self.deque.pop()\n",
      "IndexError: pop from an empty deque\n",
      "\n",
      "During handling of the above exception, another exception occurred:\n",
      "\n",
      "Traceback (most recent call last):\n",
      "  File \"/opt/spark/python/lib/py4j-0.10.7-src.zip/py4j/java_gateway.py\", line 1067, in start\n",
      "    self.socket.connect((self.address, self.port))\n",
      "ConnectionRefusedError: [Errno 111] Connection refused\n"
     ]
    },
    {
     "name": "stderr",
     "output_type": "stream",
     "text": [
      "ERROR:py4j.java_gateway:An error occurred while trying to connect to the Java server (127.0.0.1:39031)\n",
      "Traceback (most recent call last):\n",
      "  File \"/opt/conda/lib/python3.7/site-packages/IPython/core/interactiveshell.py\", line 3331, in run_code\n",
      "    exec(code_obj, self.user_global_ns, self.user_ns)\n",
      "  File \"<ipython-input-18-12ee3fb1134d>\", line 1, in <module>\n",
      "    df_mes.show(5)\n",
      "  File \"/opt/spark/python/pyspark/sql/dataframe.py\", line 378, in show\n",
      "    print(self._jdf.showString(n, 20, vertical))\n",
      "  File \"/opt/spark/python/lib/py4j-0.10.7-src.zip/py4j/java_gateway.py\", line 1257, in __call__\n",
      "    answer, self.gateway_client, self.target_id, self.name)\n",
      "  File \"/opt/spark/python/pyspark/sql/utils.py\", line 63, in deco\n",
      "    return f(*a, **kw)\n",
      "  File \"/opt/spark/python/lib/py4j-0.10.7-src.zip/py4j/protocol.py\", line 336, in get_return_value\n",
      "    format(target_id, \".\", name))\n",
      "py4j.protocol.Py4JError: An error occurred while calling o242.showString\n",
      "\n",
      "During handling of the above exception, another exception occurred:\n",
      "\n",
      "Traceback (most recent call last):\n",
      "  File \"/opt/conda/lib/python3.7/site-packages/IPython/core/interactiveshell.py\", line 2044, in showtraceback\n",
      "    stb = value._render_traceback_()\n",
      "AttributeError: 'Py4JError' object has no attribute '_render_traceback_'\n",
      "\n",
      "During handling of the above exception, another exception occurred:\n",
      "\n",
      "Traceback (most recent call last):\n",
      "  File \"/opt/spark/python/lib/py4j-0.10.7-src.zip/py4j/java_gateway.py\", line 929, in _get_connection\n",
      "    connection = self.deque.pop()\n",
      "IndexError: pop from an empty deque\n",
      "\n",
      "During handling of the above exception, another exception occurred:\n",
      "\n",
      "Traceback (most recent call last):\n",
      "  File \"/opt/spark/python/lib/py4j-0.10.7-src.zip/py4j/java_gateway.py\", line 1067, in start\n",
      "    self.socket.connect((self.address, self.port))\n",
      "ConnectionRefusedError: [Errno 111] Connection refused\n",
      "ERROR:py4j.java_gateway:An error occurred while trying to connect to the Java server (127.0.0.1:39031)\n",
      "Traceback (most recent call last):\n",
      "  File \"/opt/conda/lib/python3.7/site-packages/IPython/core/interactiveshell.py\", line 3331, in run_code\n",
      "    exec(code_obj, self.user_global_ns, self.user_ns)\n",
      "  File \"<ipython-input-18-12ee3fb1134d>\", line 1, in <module>\n",
      "    df_mes.show(5)\n",
      "  File \"/opt/spark/python/pyspark/sql/dataframe.py\", line 378, in show\n",
      "    print(self._jdf.showString(n, 20, vertical))\n",
      "  File \"/opt/spark/python/lib/py4j-0.10.7-src.zip/py4j/java_gateway.py\", line 1257, in __call__\n",
      "    answer, self.gateway_client, self.target_id, self.name)\n",
      "  File \"/opt/spark/python/pyspark/sql/utils.py\", line 63, in deco\n",
      "    return f(*a, **kw)\n",
      "  File \"/opt/spark/python/lib/py4j-0.10.7-src.zip/py4j/protocol.py\", line 336, in get_return_value\n",
      "    format(target_id, \".\", name))\n",
      "py4j.protocol.Py4JError: An error occurred while calling o242.showString\n",
      "\n",
      "During handling of the above exception, another exception occurred:\n",
      "\n",
      "Traceback (most recent call last):\n",
      "  File \"/opt/conda/lib/python3.7/site-packages/IPython/core/interactiveshell.py\", line 2044, in showtraceback\n",
      "    stb = value._render_traceback_()\n",
      "AttributeError: 'Py4JError' object has no attribute '_render_traceback_'\n",
      "\n",
      "During handling of the above exception, another exception occurred:\n",
      "\n",
      "Traceback (most recent call last):\n",
      "  File \"/opt/spark/python/lib/py4j-0.10.7-src.zip/py4j/java_gateway.py\", line 929, in _get_connection\n",
      "    connection = self.deque.pop()\n",
      "IndexError: pop from an empty deque\n",
      "\n",
      "During handling of the above exception, another exception occurred:\n",
      "\n",
      "Traceback (most recent call last):\n",
      "  File \"/opt/spark/python/lib/py4j-0.10.7-src.zip/py4j/java_gateway.py\", line 1067, in start\n",
      "    self.socket.connect((self.address, self.port))\n",
      "ConnectionRefusedError: [Errno 111] Connection refused\n",
      "ERROR:py4j.java_gateway:An error occurred while trying to connect to the Java server (127.0.0.1:39031)\n",
      "Traceback (most recent call last):\n",
      "  File \"/opt/conda/lib/python3.7/site-packages/IPython/core/interactiveshell.py\", line 3331, in run_code\n",
      "    exec(code_obj, self.user_global_ns, self.user_ns)\n",
      "  File \"<ipython-input-18-12ee3fb1134d>\", line 1, in <module>\n",
      "    df_mes.show(5)\n",
      "  File \"/opt/spark/python/pyspark/sql/dataframe.py\", line 378, in show\n",
      "    print(self._jdf.showString(n, 20, vertical))\n",
      "  File \"/opt/spark/python/lib/py4j-0.10.7-src.zip/py4j/java_gateway.py\", line 1257, in __call__\n",
      "    answer, self.gateway_client, self.target_id, self.name)\n",
      "  File \"/opt/spark/python/pyspark/sql/utils.py\", line 63, in deco\n",
      "    return f(*a, **kw)\n",
      "  File \"/opt/spark/python/lib/py4j-0.10.7-src.zip/py4j/protocol.py\", line 336, in get_return_value\n",
      "    format(target_id, \".\", name))\n",
      "py4j.protocol.Py4JError: An error occurred while calling o242.showString\n",
      "\n",
      "During handling of the above exception, another exception occurred:\n",
      "\n",
      "Traceback (most recent call last):\n",
      "  File \"/opt/conda/lib/python3.7/site-packages/IPython/core/interactiveshell.py\", line 2044, in showtraceback\n",
      "    stb = value._render_traceback_()\n",
      "AttributeError: 'Py4JError' object has no attribute '_render_traceback_'\n",
      "\n",
      "During handling of the above exception, another exception occurred:\n",
      "\n",
      "Traceback (most recent call last):\n",
      "  File \"/opt/spark/python/lib/py4j-0.10.7-src.zip/py4j/java_gateway.py\", line 929, in _get_connection\n",
      "    connection = self.deque.pop()\n",
      "IndexError: pop from an empty deque\n",
      "\n",
      "During handling of the above exception, another exception occurred:\n",
      "\n",
      "Traceback (most recent call last):\n",
      "  File \"/opt/spark/python/lib/py4j-0.10.7-src.zip/py4j/java_gateway.py\", line 1067, in start\n",
      "    self.socket.connect((self.address, self.port))\n",
      "ConnectionRefusedError: [Errno 111] Connection refused\n",
      "ERROR:py4j.java_gateway:An error occurred while trying to connect to the Java server (127.0.0.1:39031)\n",
      "Traceback (most recent call last):\n",
      "  File \"/opt/conda/lib/python3.7/site-packages/IPython/core/interactiveshell.py\", line 3331, in run_code\n",
      "    exec(code_obj, self.user_global_ns, self.user_ns)\n",
      "  File \"<ipython-input-18-12ee3fb1134d>\", line 1, in <module>\n",
      "    df_mes.show(5)\n",
      "  File \"/opt/spark/python/pyspark/sql/dataframe.py\", line 378, in show\n",
      "    print(self._jdf.showString(n, 20, vertical))\n",
      "  File \"/opt/spark/python/lib/py4j-0.10.7-src.zip/py4j/java_gateway.py\", line 1257, in __call__\n",
      "    answer, self.gateway_client, self.target_id, self.name)\n",
      "  File \"/opt/spark/python/pyspark/sql/utils.py\", line 63, in deco\n",
      "    return f(*a, **kw)\n",
      "  File \"/opt/spark/python/lib/py4j-0.10.7-src.zip/py4j/protocol.py\", line 336, in get_return_value\n",
      "    format(target_id, \".\", name))\n",
      "py4j.protocol.Py4JError: An error occurred while calling o242.showString\n",
      "\n",
      "During handling of the above exception, another exception occurred:\n",
      "\n",
      "Traceback (most recent call last):\n",
      "  File \"/opt/conda/lib/python3.7/site-packages/IPython/core/interactiveshell.py\", line 2044, in showtraceback\n",
      "    stb = value._render_traceback_()\n",
      "AttributeError: 'Py4JError' object has no attribute '_render_traceback_'\n",
      "\n",
      "During handling of the above exception, another exception occurred:\n",
      "\n",
      "Traceback (most recent call last):\n",
      "  File \"/opt/spark/python/lib/py4j-0.10.7-src.zip/py4j/java_gateway.py\", line 929, in _get_connection\n",
      "    connection = self.deque.pop()\n",
      "IndexError: pop from an empty deque\n",
      "\n",
      "During handling of the above exception, another exception occurred:\n",
      "\n",
      "Traceback (most recent call last):\n",
      "  File \"/opt/spark/python/lib/py4j-0.10.7-src.zip/py4j/java_gateway.py\", line 1067, in start\n",
      "    self.socket.connect((self.address, self.port))\n",
      "ConnectionRefusedError: [Errno 111] Connection refused\n",
      "ERROR:py4j.java_gateway:An error occurred while trying to connect to the Java server (127.0.0.1:39031)\n",
      "Traceback (most recent call last):\n",
      "  File \"/opt/conda/lib/python3.7/site-packages/IPython/core/interactiveshell.py\", line 3331, in run_code\n",
      "    exec(code_obj, self.user_global_ns, self.user_ns)\n",
      "  File \"<ipython-input-18-12ee3fb1134d>\", line 1, in <module>\n",
      "    df_mes.show(5)\n",
      "  File \"/opt/spark/python/pyspark/sql/dataframe.py\", line 378, in show\n",
      "    print(self._jdf.showString(n, 20, vertical))\n",
      "  File \"/opt/spark/python/lib/py4j-0.10.7-src.zip/py4j/java_gateway.py\", line 1257, in __call__\n",
      "    answer, self.gateway_client, self.target_id, self.name)\n",
      "  File \"/opt/spark/python/pyspark/sql/utils.py\", line 63, in deco\n",
      "    return f(*a, **kw)\n",
      "  File \"/opt/spark/python/lib/py4j-0.10.7-src.zip/py4j/protocol.py\", line 336, in get_return_value\n",
      "    format(target_id, \".\", name))\n",
      "py4j.protocol.Py4JError: An error occurred while calling o242.showString\n",
      "\n",
      "During handling of the above exception, another exception occurred:\n",
      "\n",
      "Traceback (most recent call last):\n",
      "  File \"/opt/conda/lib/python3.7/site-packages/IPython/core/interactiveshell.py\", line 2044, in showtraceback\n",
      "    stb = value._render_traceback_()\n",
      "AttributeError: 'Py4JError' object has no attribute '_render_traceback_'\n",
      "\n",
      "During handling of the above exception, another exception occurred:\n",
      "\n",
      "Traceback (most recent call last):\n",
      "  File \"/opt/spark/python/lib/py4j-0.10.7-src.zip/py4j/java_gateway.py\", line 929, in _get_connection\n",
      "    connection = self.deque.pop()\n",
      "IndexError: pop from an empty deque\n",
      "\n",
      "During handling of the above exception, another exception occurred:\n",
      "\n",
      "Traceback (most recent call last):\n",
      "  File \"/opt/spark/python/lib/py4j-0.10.7-src.zip/py4j/java_gateway.py\", line 1067, in start\n",
      "    self.socket.connect((self.address, self.port))\n",
      "ConnectionRefusedError: [Errno 111] Connection refused\n"
     ]
    },
    {
     "name": "stderr",
     "output_type": "stream",
     "text": [
      "ERROR:py4j.java_gateway:An error occurred while trying to connect to the Java server (127.0.0.1:39031)\n",
      "Traceback (most recent call last):\n",
      "  File \"/opt/conda/lib/python3.7/site-packages/IPython/core/interactiveshell.py\", line 3331, in run_code\n",
      "    exec(code_obj, self.user_global_ns, self.user_ns)\n",
      "  File \"<ipython-input-18-12ee3fb1134d>\", line 1, in <module>\n",
      "    df_mes.show(5)\n",
      "  File \"/opt/spark/python/pyspark/sql/dataframe.py\", line 378, in show\n",
      "    print(self._jdf.showString(n, 20, vertical))\n",
      "  File \"/opt/spark/python/lib/py4j-0.10.7-src.zip/py4j/java_gateway.py\", line 1257, in __call__\n",
      "    answer, self.gateway_client, self.target_id, self.name)\n",
      "  File \"/opt/spark/python/pyspark/sql/utils.py\", line 63, in deco\n",
      "    return f(*a, **kw)\n",
      "  File \"/opt/spark/python/lib/py4j-0.10.7-src.zip/py4j/protocol.py\", line 336, in get_return_value\n",
      "    format(target_id, \".\", name))\n",
      "py4j.protocol.Py4JError: An error occurred while calling o242.showString\n",
      "\n",
      "During handling of the above exception, another exception occurred:\n",
      "\n",
      "Traceback (most recent call last):\n",
      "  File \"/opt/conda/lib/python3.7/site-packages/IPython/core/interactiveshell.py\", line 2044, in showtraceback\n",
      "    stb = value._render_traceback_()\n",
      "AttributeError: 'Py4JError' object has no attribute '_render_traceback_'\n",
      "\n",
      "During handling of the above exception, another exception occurred:\n",
      "\n",
      "Traceback (most recent call last):\n",
      "  File \"/opt/spark/python/lib/py4j-0.10.7-src.zip/py4j/java_gateway.py\", line 929, in _get_connection\n",
      "    connection = self.deque.pop()\n",
      "IndexError: pop from an empty deque\n",
      "\n",
      "During handling of the above exception, another exception occurred:\n",
      "\n",
      "Traceback (most recent call last):\n",
      "  File \"/opt/spark/python/lib/py4j-0.10.7-src.zip/py4j/java_gateway.py\", line 1067, in start\n",
      "    self.socket.connect((self.address, self.port))\n",
      "ConnectionRefusedError: [Errno 111] Connection refused\n",
      "ERROR:py4j.java_gateway:An error occurred while trying to connect to the Java server (127.0.0.1:39031)\n",
      "Traceback (most recent call last):\n",
      "  File \"/opt/conda/lib/python3.7/site-packages/IPython/core/interactiveshell.py\", line 3331, in run_code\n",
      "    exec(code_obj, self.user_global_ns, self.user_ns)\n",
      "  File \"<ipython-input-18-12ee3fb1134d>\", line 1, in <module>\n",
      "    df_mes.show(5)\n",
      "  File \"/opt/spark/python/pyspark/sql/dataframe.py\", line 378, in show\n",
      "    print(self._jdf.showString(n, 20, vertical))\n",
      "  File \"/opt/spark/python/lib/py4j-0.10.7-src.zip/py4j/java_gateway.py\", line 1257, in __call__\n",
      "    answer, self.gateway_client, self.target_id, self.name)\n",
      "  File \"/opt/spark/python/pyspark/sql/utils.py\", line 63, in deco\n",
      "    return f(*a, **kw)\n",
      "  File \"/opt/spark/python/lib/py4j-0.10.7-src.zip/py4j/protocol.py\", line 336, in get_return_value\n",
      "    format(target_id, \".\", name))\n",
      "py4j.protocol.Py4JError: An error occurred while calling o242.showString\n",
      "\n",
      "During handling of the above exception, another exception occurred:\n",
      "\n",
      "Traceback (most recent call last):\n",
      "  File \"/opt/conda/lib/python3.7/site-packages/IPython/core/interactiveshell.py\", line 2044, in showtraceback\n",
      "    stb = value._render_traceback_()\n",
      "AttributeError: 'Py4JError' object has no attribute '_render_traceback_'\n",
      "\n",
      "During handling of the above exception, another exception occurred:\n",
      "\n",
      "Traceback (most recent call last):\n",
      "  File \"/opt/spark/python/lib/py4j-0.10.7-src.zip/py4j/java_gateway.py\", line 929, in _get_connection\n",
      "    connection = self.deque.pop()\n",
      "IndexError: pop from an empty deque\n",
      "\n",
      "During handling of the above exception, another exception occurred:\n",
      "\n",
      "Traceback (most recent call last):\n",
      "  File \"/opt/spark/python/lib/py4j-0.10.7-src.zip/py4j/java_gateway.py\", line 1067, in start\n",
      "    self.socket.connect((self.address, self.port))\n",
      "ConnectionRefusedError: [Errno 111] Connection refused\n",
      "ERROR:py4j.java_gateway:An error occurred while trying to connect to the Java server (127.0.0.1:39031)\n",
      "Traceback (most recent call last):\n",
      "  File \"/opt/conda/lib/python3.7/site-packages/IPython/core/interactiveshell.py\", line 3331, in run_code\n",
      "    exec(code_obj, self.user_global_ns, self.user_ns)\n",
      "  File \"<ipython-input-18-12ee3fb1134d>\", line 1, in <module>\n",
      "    df_mes.show(5)\n",
      "  File \"/opt/spark/python/pyspark/sql/dataframe.py\", line 378, in show\n",
      "    print(self._jdf.showString(n, 20, vertical))\n",
      "  File \"/opt/spark/python/lib/py4j-0.10.7-src.zip/py4j/java_gateway.py\", line 1257, in __call__\n",
      "    answer, self.gateway_client, self.target_id, self.name)\n",
      "  File \"/opt/spark/python/pyspark/sql/utils.py\", line 63, in deco\n",
      "    return f(*a, **kw)\n",
      "  File \"/opt/spark/python/lib/py4j-0.10.7-src.zip/py4j/protocol.py\", line 336, in get_return_value\n",
      "    format(target_id, \".\", name))\n",
      "py4j.protocol.Py4JError: An error occurred while calling o242.showString\n",
      "\n",
      "During handling of the above exception, another exception occurred:\n",
      "\n",
      "Traceback (most recent call last):\n",
      "  File \"/opt/conda/lib/python3.7/site-packages/IPython/core/interactiveshell.py\", line 2044, in showtraceback\n",
      "    stb = value._render_traceback_()\n",
      "AttributeError: 'Py4JError' object has no attribute '_render_traceback_'\n",
      "\n",
      "During handling of the above exception, another exception occurred:\n",
      "\n",
      "Traceback (most recent call last):\n",
      "  File \"/opt/spark/python/lib/py4j-0.10.7-src.zip/py4j/java_gateway.py\", line 929, in _get_connection\n",
      "    connection = self.deque.pop()\n",
      "IndexError: pop from an empty deque\n",
      "\n",
      "During handling of the above exception, another exception occurred:\n",
      "\n",
      "Traceback (most recent call last):\n",
      "  File \"/opt/spark/python/lib/py4j-0.10.7-src.zip/py4j/java_gateway.py\", line 1067, in start\n",
      "    self.socket.connect((self.address, self.port))\n",
      "ConnectionRefusedError: [Errno 111] Connection refused\n",
      "ERROR:py4j.java_gateway:An error occurred while trying to connect to the Java server (127.0.0.1:39031)\n",
      "Traceback (most recent call last):\n",
      "  File \"/opt/conda/lib/python3.7/site-packages/IPython/core/interactiveshell.py\", line 3331, in run_code\n",
      "    exec(code_obj, self.user_global_ns, self.user_ns)\n",
      "  File \"<ipython-input-18-12ee3fb1134d>\", line 1, in <module>\n",
      "    df_mes.show(5)\n",
      "  File \"/opt/spark/python/pyspark/sql/dataframe.py\", line 378, in show\n",
      "    print(self._jdf.showString(n, 20, vertical))\n",
      "  File \"/opt/spark/python/lib/py4j-0.10.7-src.zip/py4j/java_gateway.py\", line 1257, in __call__\n",
      "    answer, self.gateway_client, self.target_id, self.name)\n",
      "  File \"/opt/spark/python/pyspark/sql/utils.py\", line 63, in deco\n",
      "    return f(*a, **kw)\n",
      "  File \"/opt/spark/python/lib/py4j-0.10.7-src.zip/py4j/protocol.py\", line 336, in get_return_value\n",
      "    format(target_id, \".\", name))\n",
      "py4j.protocol.Py4JError: An error occurred while calling o242.showString\n",
      "\n",
      "During handling of the above exception, another exception occurred:\n",
      "\n",
      "Traceback (most recent call last):\n",
      "  File \"/opt/conda/lib/python3.7/site-packages/IPython/core/interactiveshell.py\", line 2044, in showtraceback\n",
      "    stb = value._render_traceback_()\n",
      "AttributeError: 'Py4JError' object has no attribute '_render_traceback_'\n",
      "\n",
      "During handling of the above exception, another exception occurred:\n",
      "\n",
      "Traceback (most recent call last):\n",
      "  File \"/opt/spark/python/lib/py4j-0.10.7-src.zip/py4j/java_gateway.py\", line 929, in _get_connection\n",
      "    connection = self.deque.pop()\n",
      "IndexError: pop from an empty deque\n",
      "\n",
      "During handling of the above exception, another exception occurred:\n",
      "\n",
      "Traceback (most recent call last):\n",
      "  File \"/opt/spark/python/lib/py4j-0.10.7-src.zip/py4j/java_gateway.py\", line 1067, in start\n",
      "    self.socket.connect((self.address, self.port))\n",
      "ConnectionRefusedError: [Errno 111] Connection refused\n",
      "ERROR:py4j.java_gateway:An error occurred while trying to connect to the Java server (127.0.0.1:39031)\n",
      "Traceback (most recent call last):\n",
      "  File \"/opt/conda/lib/python3.7/site-packages/IPython/core/interactiveshell.py\", line 3331, in run_code\n",
      "    exec(code_obj, self.user_global_ns, self.user_ns)\n",
      "  File \"<ipython-input-18-12ee3fb1134d>\", line 1, in <module>\n",
      "    df_mes.show(5)\n",
      "  File \"/opt/spark/python/pyspark/sql/dataframe.py\", line 378, in show\n",
      "    print(self._jdf.showString(n, 20, vertical))\n",
      "  File \"/opt/spark/python/lib/py4j-0.10.7-src.zip/py4j/java_gateway.py\", line 1257, in __call__\n",
      "    answer, self.gateway_client, self.target_id, self.name)\n",
      "  File \"/opt/spark/python/pyspark/sql/utils.py\", line 63, in deco\n",
      "    return f(*a, **kw)\n",
      "  File \"/opt/spark/python/lib/py4j-0.10.7-src.zip/py4j/protocol.py\", line 336, in get_return_value\n",
      "    format(target_id, \".\", name))\n",
      "py4j.protocol.Py4JError: An error occurred while calling o242.showString\n",
      "\n",
      "During handling of the above exception, another exception occurred:\n",
      "\n",
      "Traceback (most recent call last):\n",
      "  File \"/opt/conda/lib/python3.7/site-packages/IPython/core/interactiveshell.py\", line 2044, in showtraceback\n",
      "    stb = value._render_traceback_()\n",
      "AttributeError: 'Py4JError' object has no attribute '_render_traceback_'\n",
      "\n",
      "During handling of the above exception, another exception occurred:\n",
      "\n",
      "Traceback (most recent call last):\n",
      "  File \"/opt/spark/python/lib/py4j-0.10.7-src.zip/py4j/java_gateway.py\", line 929, in _get_connection\n",
      "    connection = self.deque.pop()\n",
      "IndexError: pop from an empty deque\n",
      "\n",
      "During handling of the above exception, another exception occurred:\n",
      "\n",
      "Traceback (most recent call last):\n",
      "  File \"/opt/spark/python/lib/py4j-0.10.7-src.zip/py4j/java_gateway.py\", line 1067, in start\n",
      "    self.socket.connect((self.address, self.port))\n",
      "ConnectionRefusedError: [Errno 111] Connection refused\n"
     ]
    },
    {
     "name": "stderr",
     "output_type": "stream",
     "text": [
      "ERROR:py4j.java_gateway:An error occurred while trying to connect to the Java server (127.0.0.1:39031)\n",
      "Traceback (most recent call last):\n",
      "  File \"/opt/conda/lib/python3.7/site-packages/IPython/core/interactiveshell.py\", line 3331, in run_code\n",
      "    exec(code_obj, self.user_global_ns, self.user_ns)\n",
      "  File \"<ipython-input-18-12ee3fb1134d>\", line 1, in <module>\n",
      "    df_mes.show(5)\n",
      "  File \"/opt/spark/python/pyspark/sql/dataframe.py\", line 378, in show\n",
      "    print(self._jdf.showString(n, 20, vertical))\n",
      "  File \"/opt/spark/python/lib/py4j-0.10.7-src.zip/py4j/java_gateway.py\", line 1257, in __call__\n",
      "    answer, self.gateway_client, self.target_id, self.name)\n",
      "  File \"/opt/spark/python/pyspark/sql/utils.py\", line 63, in deco\n",
      "    return f(*a, **kw)\n",
      "  File \"/opt/spark/python/lib/py4j-0.10.7-src.zip/py4j/protocol.py\", line 336, in get_return_value\n",
      "    format(target_id, \".\", name))\n",
      "py4j.protocol.Py4JError: An error occurred while calling o242.showString\n",
      "\n",
      "During handling of the above exception, another exception occurred:\n",
      "\n",
      "Traceback (most recent call last):\n",
      "  File \"/opt/conda/lib/python3.7/site-packages/IPython/core/interactiveshell.py\", line 2044, in showtraceback\n",
      "    stb = value._render_traceback_()\n",
      "AttributeError: 'Py4JError' object has no attribute '_render_traceback_'\n",
      "\n",
      "During handling of the above exception, another exception occurred:\n",
      "\n",
      "Traceback (most recent call last):\n",
      "  File \"/opt/spark/python/lib/py4j-0.10.7-src.zip/py4j/java_gateway.py\", line 929, in _get_connection\n",
      "    connection = self.deque.pop()\n",
      "IndexError: pop from an empty deque\n",
      "\n",
      "During handling of the above exception, another exception occurred:\n",
      "\n",
      "Traceback (most recent call last):\n",
      "  File \"/opt/spark/python/lib/py4j-0.10.7-src.zip/py4j/java_gateway.py\", line 1067, in start\n",
      "    self.socket.connect((self.address, self.port))\n",
      "ConnectionRefusedError: [Errno 111] Connection refused\n",
      "ERROR:py4j.java_gateway:An error occurred while trying to connect to the Java server (127.0.0.1:39031)\n",
      "Traceback (most recent call last):\n",
      "  File \"/opt/conda/lib/python3.7/site-packages/IPython/core/interactiveshell.py\", line 3331, in run_code\n",
      "    exec(code_obj, self.user_global_ns, self.user_ns)\n",
      "  File \"<ipython-input-18-12ee3fb1134d>\", line 1, in <module>\n",
      "    df_mes.show(5)\n",
      "  File \"/opt/spark/python/pyspark/sql/dataframe.py\", line 378, in show\n",
      "    print(self._jdf.showString(n, 20, vertical))\n",
      "  File \"/opt/spark/python/lib/py4j-0.10.7-src.zip/py4j/java_gateway.py\", line 1257, in __call__\n",
      "    answer, self.gateway_client, self.target_id, self.name)\n",
      "  File \"/opt/spark/python/pyspark/sql/utils.py\", line 63, in deco\n",
      "    return f(*a, **kw)\n",
      "  File \"/opt/spark/python/lib/py4j-0.10.7-src.zip/py4j/protocol.py\", line 336, in get_return_value\n",
      "    format(target_id, \".\", name))\n",
      "py4j.protocol.Py4JError: An error occurred while calling o242.showString\n",
      "\n",
      "During handling of the above exception, another exception occurred:\n",
      "\n",
      "Traceback (most recent call last):\n",
      "  File \"/opt/conda/lib/python3.7/site-packages/IPython/core/interactiveshell.py\", line 2044, in showtraceback\n",
      "    stb = value._render_traceback_()\n",
      "AttributeError: 'Py4JError' object has no attribute '_render_traceback_'\n",
      "\n",
      "During handling of the above exception, another exception occurred:\n",
      "\n",
      "Traceback (most recent call last):\n",
      "  File \"/opt/spark/python/lib/py4j-0.10.7-src.zip/py4j/java_gateway.py\", line 929, in _get_connection\n",
      "    connection = self.deque.pop()\n",
      "IndexError: pop from an empty deque\n",
      "\n",
      "During handling of the above exception, another exception occurred:\n",
      "\n",
      "Traceback (most recent call last):\n",
      "  File \"/opt/spark/python/lib/py4j-0.10.7-src.zip/py4j/java_gateway.py\", line 1067, in start\n",
      "    self.socket.connect((self.address, self.port))\n",
      "ConnectionRefusedError: [Errno 111] Connection refused\n"
     ]
    },
    {
     "ename": "Py4JError",
     "evalue": "An error occurred while calling o242.showString",
     "output_type": "error",
     "traceback": [
      "\u001b[0;31m---------------------------------------------------------------------------\u001b[0m",
      "\u001b[0;31mPy4JError\u001b[0m                                 Traceback (most recent call last)",
      "\u001b[0;32m<ipython-input-18-12ee3fb1134d>\u001b[0m in \u001b[0;36m<module>\u001b[0;34m\u001b[0m\n\u001b[0;32m----> 1\u001b[0;31m \u001b[0mdf_mes\u001b[0m\u001b[0;34m.\u001b[0m\u001b[0mshow\u001b[0m\u001b[0;34m(\u001b[0m\u001b[0;36m5\u001b[0m\u001b[0;34m)\u001b[0m\u001b[0;34m\u001b[0m\u001b[0;34m\u001b[0m\u001b[0m\n\u001b[0m",
      "\u001b[0;32m/opt/spark/python/pyspark/sql/dataframe.py\u001b[0m in \u001b[0;36mshow\u001b[0;34m(self, n, truncate, vertical)\u001b[0m\n\u001b[1;32m    376\u001b[0m         \"\"\"\n\u001b[1;32m    377\u001b[0m         \u001b[0;32mif\u001b[0m \u001b[0misinstance\u001b[0m\u001b[0;34m(\u001b[0m\u001b[0mtruncate\u001b[0m\u001b[0;34m,\u001b[0m \u001b[0mbool\u001b[0m\u001b[0;34m)\u001b[0m \u001b[0;32mand\u001b[0m \u001b[0mtruncate\u001b[0m\u001b[0;34m:\u001b[0m\u001b[0;34m\u001b[0m\u001b[0;34m\u001b[0m\u001b[0m\n\u001b[0;32m--> 378\u001b[0;31m             \u001b[0mprint\u001b[0m\u001b[0;34m(\u001b[0m\u001b[0mself\u001b[0m\u001b[0;34m.\u001b[0m\u001b[0m_jdf\u001b[0m\u001b[0;34m.\u001b[0m\u001b[0mshowString\u001b[0m\u001b[0;34m(\u001b[0m\u001b[0mn\u001b[0m\u001b[0;34m,\u001b[0m \u001b[0;36m20\u001b[0m\u001b[0;34m,\u001b[0m \u001b[0mvertical\u001b[0m\u001b[0;34m)\u001b[0m\u001b[0;34m)\u001b[0m\u001b[0;34m\u001b[0m\u001b[0;34m\u001b[0m\u001b[0m\n\u001b[0m\u001b[1;32m    379\u001b[0m         \u001b[0;32melse\u001b[0m\u001b[0;34m:\u001b[0m\u001b[0;34m\u001b[0m\u001b[0;34m\u001b[0m\u001b[0m\n\u001b[1;32m    380\u001b[0m             \u001b[0mprint\u001b[0m\u001b[0;34m(\u001b[0m\u001b[0mself\u001b[0m\u001b[0;34m.\u001b[0m\u001b[0m_jdf\u001b[0m\u001b[0;34m.\u001b[0m\u001b[0mshowString\u001b[0m\u001b[0;34m(\u001b[0m\u001b[0mn\u001b[0m\u001b[0;34m,\u001b[0m \u001b[0mint\u001b[0m\u001b[0;34m(\u001b[0m\u001b[0mtruncate\u001b[0m\u001b[0;34m)\u001b[0m\u001b[0;34m,\u001b[0m \u001b[0mvertical\u001b[0m\u001b[0;34m)\u001b[0m\u001b[0;34m)\u001b[0m\u001b[0;34m\u001b[0m\u001b[0;34m\u001b[0m\u001b[0m\n",
      "\u001b[0;32m/opt/spark/python/lib/py4j-0.10.7-src.zip/py4j/java_gateway.py\u001b[0m in \u001b[0;36m__call__\u001b[0;34m(self, *args)\u001b[0m\n\u001b[1;32m   1255\u001b[0m         \u001b[0manswer\u001b[0m \u001b[0;34m=\u001b[0m \u001b[0mself\u001b[0m\u001b[0;34m.\u001b[0m\u001b[0mgateway_client\u001b[0m\u001b[0;34m.\u001b[0m\u001b[0msend_command\u001b[0m\u001b[0;34m(\u001b[0m\u001b[0mcommand\u001b[0m\u001b[0;34m)\u001b[0m\u001b[0;34m\u001b[0m\u001b[0;34m\u001b[0m\u001b[0m\n\u001b[1;32m   1256\u001b[0m         return_value = get_return_value(\n\u001b[0;32m-> 1257\u001b[0;31m             answer, self.gateway_client, self.target_id, self.name)\n\u001b[0m\u001b[1;32m   1258\u001b[0m \u001b[0;34m\u001b[0m\u001b[0m\n\u001b[1;32m   1259\u001b[0m         \u001b[0;32mfor\u001b[0m \u001b[0mtemp_arg\u001b[0m \u001b[0;32min\u001b[0m \u001b[0mtemp_args\u001b[0m\u001b[0;34m:\u001b[0m\u001b[0;34m\u001b[0m\u001b[0;34m\u001b[0m\u001b[0m\n",
      "\u001b[0;32m/opt/spark/python/pyspark/sql/utils.py\u001b[0m in \u001b[0;36mdeco\u001b[0;34m(*a, **kw)\u001b[0m\n\u001b[1;32m     61\u001b[0m     \u001b[0;32mdef\u001b[0m \u001b[0mdeco\u001b[0m\u001b[0;34m(\u001b[0m\u001b[0;34m*\u001b[0m\u001b[0ma\u001b[0m\u001b[0;34m,\u001b[0m \u001b[0;34m**\u001b[0m\u001b[0mkw\u001b[0m\u001b[0;34m)\u001b[0m\u001b[0;34m:\u001b[0m\u001b[0;34m\u001b[0m\u001b[0;34m\u001b[0m\u001b[0m\n\u001b[1;32m     62\u001b[0m         \u001b[0;32mtry\u001b[0m\u001b[0;34m:\u001b[0m\u001b[0;34m\u001b[0m\u001b[0;34m\u001b[0m\u001b[0m\n\u001b[0;32m---> 63\u001b[0;31m             \u001b[0;32mreturn\u001b[0m \u001b[0mf\u001b[0m\u001b[0;34m(\u001b[0m\u001b[0;34m*\u001b[0m\u001b[0ma\u001b[0m\u001b[0;34m,\u001b[0m \u001b[0;34m**\u001b[0m\u001b[0mkw\u001b[0m\u001b[0;34m)\u001b[0m\u001b[0;34m\u001b[0m\u001b[0;34m\u001b[0m\u001b[0m\n\u001b[0m\u001b[1;32m     64\u001b[0m         \u001b[0;32mexcept\u001b[0m \u001b[0mpy4j\u001b[0m\u001b[0;34m.\u001b[0m\u001b[0mprotocol\u001b[0m\u001b[0;34m.\u001b[0m\u001b[0mPy4JJavaError\u001b[0m \u001b[0;32mas\u001b[0m \u001b[0me\u001b[0m\u001b[0;34m:\u001b[0m\u001b[0;34m\u001b[0m\u001b[0;34m\u001b[0m\u001b[0m\n\u001b[1;32m     65\u001b[0m             \u001b[0ms\u001b[0m \u001b[0;34m=\u001b[0m \u001b[0me\u001b[0m\u001b[0;34m.\u001b[0m\u001b[0mjava_exception\u001b[0m\u001b[0;34m.\u001b[0m\u001b[0mtoString\u001b[0m\u001b[0;34m(\u001b[0m\u001b[0;34m)\u001b[0m\u001b[0;34m\u001b[0m\u001b[0;34m\u001b[0m\u001b[0m\n",
      "\u001b[0;32m/opt/spark/python/lib/py4j-0.10.7-src.zip/py4j/protocol.py\u001b[0m in \u001b[0;36mget_return_value\u001b[0;34m(answer, gateway_client, target_id, name)\u001b[0m\n\u001b[1;32m    334\u001b[0m             raise Py4JError(\n\u001b[1;32m    335\u001b[0m                 \u001b[0;34m\"An error occurred while calling {0}{1}{2}\"\u001b[0m\u001b[0;34m.\u001b[0m\u001b[0;34m\u001b[0m\u001b[0;34m\u001b[0m\u001b[0m\n\u001b[0;32m--> 336\u001b[0;31m                 format(target_id, \".\", name))\n\u001b[0m\u001b[1;32m    337\u001b[0m     \u001b[0;32melse\u001b[0m\u001b[0;34m:\u001b[0m\u001b[0;34m\u001b[0m\u001b[0;34m\u001b[0m\u001b[0m\n\u001b[1;32m    338\u001b[0m         \u001b[0mtype\u001b[0m \u001b[0;34m=\u001b[0m \u001b[0manswer\u001b[0m\u001b[0;34m[\u001b[0m\u001b[0;36m1\u001b[0m\u001b[0;34m]\u001b[0m\u001b[0;34m\u001b[0m\u001b[0;34m\u001b[0m\u001b[0m\n",
      "\u001b[0;31mPy4JError\u001b[0m: An error occurred while calling o242.showString"
     ]
    }
   ],
   "source": [
    "df_mes.show(5)"
   ]
  },
  {
   "cell_type": "code",
   "execution_count": 15,
   "metadata": {},
   "outputs": [
    {
     "name": "stdout",
     "output_type": "stream",
     "text": [
      "+-------------------+----+--------+-------+--------+--------+\n",
      "|               Date|Base|     SKU|    IBM|  Volume|Segmento|\n",
      "+-------------------+----+--------+-------+--------+--------+\n",
      "|2019-07-10 00:00:00|ABAH|15521801|1032793| 26969.0|       A|\n",
      "|2019-07-10 00:00:00|ABAH|15526801|1000030|142958.0|       A|\n",
      "|2019-07-10 00:00:00|ABAR|15521801|1033788|   519.0|       A|\n",
      "|2019-07-10 00:00:00|ABAR|15532801|1056551|   708.0|       A|\n",
      "|2019-07-10 00:00:00|ABCH|15521801|1035814|     0.0|       A|\n",
      "+-------------------+----+--------+-------+--------+--------+\n",
      "only showing top 5 rows\n",
      "\n"
     ]
    }
   ],
   "source": [
    "df_vendas_dia.show(5)"
   ]
  },
  {
   "cell_type": "code",
   "execution_count": 15,
   "metadata": {},
   "outputs": [
    {
     "name": "stdout",
     "output_type": "stream",
     "text": [
      "+-------------------+----+--------+-------+--------+-----------+\n",
      "|               Date|Base|     SKU|    IBM|Segmento|sum(Volume)|\n",
      "+-------------------+----+--------+-------+--------+-----------+\n",
      "|2019-07-10 00:00:00|BBAR|22150801|1023648|       V|     5050.0|\n",
      "|2019-07-10 00:00:00|BBAR|27007801|1031446|       V|    10000.0|\n",
      "|2019-07-10 00:00:00|BBAU|24318801|1038031|       V|     5000.0|\n",
      "|2019-07-10 00:00:00|BCAX|24144801|1047499|       V|     5000.0|\n",
      "|2019-07-10 00:00:00|BCAX|27007801|1039624|       V|     5000.0|\n",
      "|2019-07-10 00:00:00|BCEL|24144801| 681261|       V|     5000.0|\n",
      "|2019-07-10 00:00:00|BEMT|24319801|1040382|       C|    34500.0|\n",
      "|2019-07-10 00:00:00|BEST|22146801|1046885|       V|    20000.0|\n",
      "|2019-07-10 00:00:00|BEST|22149801|1038121|       V|     5000.0|\n",
      "|2019-07-10 00:00:00|BFOR|22149801| 875562|       V|    10000.0|\n",
      "|2019-07-10 00:00:00|BGOI|24141801|1062223|       C|    10000.0|\n",
      "|2019-07-10 00:00:00| BIP|22149801|1030062|       V|     5000.0|\n",
      "|2019-07-10 00:00:00| BIP|22150801|1023111|       V|     5000.0|\n",
      "|2019-07-10 00:00:00| BIP|24141801|1038963|       C|     5000.0|\n",
      "|2019-07-10 00:00:00| BIP|24146801|1016713|       V|     5000.0|\n",
      "|2019-07-10 00:00:00| BIP|24319801| 632899|       C|    25000.0|\n",
      "|2019-07-10 00:00:00| BIP|27280801|1021059|       V|     5000.0|\n",
      "|2019-07-10 00:00:00|BJOC|24319801|1019103|       C|    10000.0|\n",
      "|2019-07-10 00:00:00|BJOC|27280801|1014917|       V|    10000.0|\n",
      "|2019-07-10 00:00:00|BMAC|22149801|1016872|       V|     5000.0|\n",
      "+-------------------+----+--------+-------+--------+-----------+\n",
      "only showing top 20 rows\n",
      "\n"
     ]
    }
   ],
   "source": [
    "df_vendas_dia.groupBy(\"Date\", \"Base\", \"SKU\", \"IBM\",\"Segmento\").agg({\"Volume\": \"sum\"}).show()"
   ]
  },
  {
   "cell_type": "code",
   "execution_count": null,
   "metadata": {},
   "outputs": [],
   "source": []
  },
  {
   "cell_type": "code",
   "execution_count": null,
   "metadata": {},
   "outputs": [],
   "source": []
  },
  {
   "cell_type": "code",
   "execution_count": null,
   "metadata": {},
   "outputs": [],
   "source": []
  },
  {
   "cell_type": "code",
   "execution_count": null,
   "metadata": {},
   "outputs": [],
   "source": []
  },
  {
   "cell_type": "code",
   "execution_count": 16,
   "metadata": {},
   "outputs": [
    {
     "name": "stdout",
     "output_type": "stream",
     "text": [
      "Collecting pyarrow\n",
      "  Using cached pyarrow-0.16.0-cp37-cp37m-manylinux2014_x86_64.whl (63.1 MB)\n",
      "Requirement already satisfied: numpy>=1.14 in /opt/conda/lib/python3.7/site-packages (from pyarrow) (1.18.1)\n",
      "Requirement already satisfied: six>=1.0.0 in /opt/conda/lib/python3.7/site-packages (from pyarrow) (1.14.0)\n",
      "Installing collected packages: pyarrow\n",
      "Successfully installed pyarrow-0.16.0\n"
     ]
    }
   ],
   "source": [
    "!pip install pyarrow"
   ]
  },
  {
   "cell_type": "code",
   "execution_count": 16,
   "metadata": {},
   "outputs": [],
   "source": [
    "import plotly.express as px\n"
   ]
  },
  {
   "cell_type": "code",
   "execution_count": 14,
   "metadata": {},
   "outputs": [],
   "source": [
    "vendas_dia_group = df_vendas_dia.groupBy(\"Date\", \"Base\", \"SKU\", \"IBM\",\"Segmento\").agg({\"Volume\": \"sum\"})\n"
   ]
  },
  {
   "cell_type": "code",
   "execution_count": 18,
   "metadata": {},
   "outputs": [
    {
     "name": "stdout",
     "output_type": "stream",
     "text": [
      "+-------------------+----+--------+-------+--------+-----------+\n",
      "|               Date|Base|     SKU|    IBM|Segmento|sum(Volume)|\n",
      "+-------------------+----+--------+-------+--------+-----------+\n",
      "|2019-07-10 00:00:00|BBAR|22150801|1023648|       V|     5050.0|\n",
      "|2019-07-10 00:00:00|BBAR|27007801|1031446|       V|    10000.0|\n",
      "|2019-07-10 00:00:00|BBAU|24318801|1038031|       V|     5000.0|\n",
      "|2019-07-10 00:00:00|BCAX|24144801|1047499|       V|     5000.0|\n",
      "|2019-07-10 00:00:00|BCAX|27007801|1039624|       V|     5000.0|\n",
      "|2019-07-10 00:00:00|BCEL|24144801| 681261|       V|     5000.0|\n",
      "|2019-07-10 00:00:00|BEMT|24319801|1040382|       C|    34500.0|\n",
      "|2019-07-10 00:00:00|BEST|22146801|1046885|       V|    20000.0|\n",
      "|2019-07-10 00:00:00|BEST|22149801|1038121|       V|     5000.0|\n",
      "|2019-07-10 00:00:00|BFOR|22149801| 875562|       V|    10000.0|\n",
      "|2019-07-10 00:00:00|BGOI|24141801|1062223|       C|    10000.0|\n",
      "|2019-07-10 00:00:00| BIP|22149801|1030062|       V|     5000.0|\n",
      "|2019-07-10 00:00:00| BIP|22150801|1023111|       V|     5000.0|\n",
      "|2019-07-10 00:00:00| BIP|24141801|1038963|       C|     5000.0|\n",
      "|2019-07-10 00:00:00| BIP|24146801|1016713|       V|     5000.0|\n",
      "|2019-07-10 00:00:00| BIP|24319801| 632899|       C|    25000.0|\n",
      "|2019-07-10 00:00:00| BIP|27280801|1021059|       V|     5000.0|\n",
      "|2019-07-10 00:00:00|BJOC|24319801|1019103|       C|    10000.0|\n",
      "|2019-07-10 00:00:00|BJOC|27280801|1014917|       V|    10000.0|\n",
      "|2019-07-10 00:00:00|BMAC|22149801|1016872|       V|     5000.0|\n",
      "+-------------------+----+--------+-------+--------+-----------+\n",
      "only showing top 20 rows\n",
      "\n"
     ]
    }
   ],
   "source": [
    "vendas_dia_group.show()"
   ]
  },
  {
   "cell_type": "code",
   "execution_count": 15,
   "metadata": {},
   "outputs": [
    {
     "name": "stderr",
     "output_type": "stream",
     "text": [
      "/opt/spark/python/pyspark/sql/dataframe.py:2102: UserWarning: toPandas attempted Arrow optimization because 'spark.sql.execution.arrow.enabled' is set to true; however, failed by the reason below:\n",
      "  PyArrow >= 0.8.0 must be installed; however, it was not found.\n",
      "Attempting non-optimization as 'spark.sql.execution.arrow.fallback.enabled' is set to true.\n",
      "  warnings.warn(msg)\n"
     ]
    },
    {
     "ename": "Py4JJavaError",
     "evalue": "An error occurred while calling o169.collectToPython.\n: org.apache.spark.SparkException: Job aborted due to stage failure: Task 13 in stage 7.0 failed 1 times, most recent failure: Lost task 13.0 in stage 7.0 (TID 433, localhost, executor driver): ExecutorLostFailure (executor driver exited caused by one of the running tasks) Reason: Executor heartbeat timed out after 451499 ms\nDriver stacktrace:\n\tat org.apache.spark.scheduler.DAGScheduler.failJobAndIndependentStages(DAGScheduler.scala:1889)\n\tat org.apache.spark.scheduler.DAGScheduler.$anonfun$abortStage$2(DAGScheduler.scala:1877)\n\tat org.apache.spark.scheduler.DAGScheduler.$anonfun$abortStage$2$adapted(DAGScheduler.scala:1876)\n\tat scala.collection.mutable.ResizableArray.foreach(ResizableArray.scala:62)\n\tat scala.collection.mutable.ResizableArray.foreach$(ResizableArray.scala:55)\n\tat scala.collection.mutable.ArrayBuffer.foreach(ArrayBuffer.scala:49)\n\tat org.apache.spark.scheduler.DAGScheduler.abortStage(DAGScheduler.scala:1876)\n\tat org.apache.spark.scheduler.DAGScheduler.$anonfun$handleTaskSetFailed$1(DAGScheduler.scala:926)\n\tat org.apache.spark.scheduler.DAGScheduler.$anonfun$handleTaskSetFailed$1$adapted(DAGScheduler.scala:926)\n\tat scala.Option.foreach(Option.scala:274)\n\tat org.apache.spark.scheduler.DAGScheduler.handleTaskSetFailed(DAGScheduler.scala:926)\n\tat org.apache.spark.scheduler.DAGSchedulerEventProcessLoop.doOnReceive(DAGScheduler.scala:2110)\n\tat org.apache.spark.scheduler.DAGSchedulerEventProcessLoop.onReceive(DAGScheduler.scala:2059)\n\tat org.apache.spark.scheduler.DAGSchedulerEventProcessLoop.onReceive(DAGScheduler.scala:2048)\n\tat org.apache.spark.util.EventLoop$$anon$1.run(EventLoop.scala:49)\n\tat org.apache.spark.scheduler.DAGScheduler.runJob(DAGScheduler.scala:737)\n\tat org.apache.spark.SparkContext.runJob(SparkContext.scala:2061)\n\tat org.apache.spark.SparkContext.runJob(SparkContext.scala:2082)\n\tat org.apache.spark.SparkContext.runJob(SparkContext.scala:2101)\n\tat org.apache.spark.SparkContext.runJob(SparkContext.scala:2126)\n\tat org.apache.spark.rdd.RDD.$anonfun$collect$1(RDD.scala:945)\n\tat org.apache.spark.rdd.RDDOperationScope$.withScope(RDDOperationScope.scala:151)\n\tat org.apache.spark.rdd.RDDOperationScope$.withScope(RDDOperationScope.scala:112)\n\tat org.apache.spark.rdd.RDD.withScope(RDD.scala:363)\n\tat org.apache.spark.rdd.RDD.collect(RDD.scala:944)\n\tat org.apache.spark.sql.execution.SparkPlan.executeCollect(SparkPlan.scala:299)\n\tat org.apache.spark.sql.Dataset.$anonfun$collectToPython$1(Dataset.scala:3257)\n\tat org.apache.spark.sql.Dataset.$anonfun$withAction$2(Dataset.scala:3364)\n\tat org.apache.spark.sql.execution.SQLExecution$.$anonfun$withNewExecutionId$1(SQLExecution.scala:78)\n\tat org.apache.spark.sql.execution.SQLExecution$.withSQLConfPropagated(SQLExecution.scala:125)\n\tat org.apache.spark.sql.execution.SQLExecution$.withNewExecutionId(SQLExecution.scala:73)\n\tat org.apache.spark.sql.Dataset.withAction(Dataset.scala:3364)\n\tat org.apache.spark.sql.Dataset.collectToPython(Dataset.scala:3254)\n\tat java.base/jdk.internal.reflect.NativeMethodAccessorImpl.invoke0(Native Method)\n\tat java.base/jdk.internal.reflect.NativeMethodAccessorImpl.invoke(NativeMethodAccessorImpl.java:62)\n\tat java.base/jdk.internal.reflect.DelegatingMethodAccessorImpl.invoke(DelegatingMethodAccessorImpl.java:43)\n\tat java.base/java.lang.reflect.Method.invoke(Method.java:566)\n\tat py4j.reflection.MethodInvoker.invoke(MethodInvoker.java:244)\n\tat py4j.reflection.ReflectionEngine.invoke(ReflectionEngine.java:357)\n\tat py4j.Gateway.invoke(Gateway.java:282)\n\tat py4j.commands.AbstractCommand.invokeMethod(AbstractCommand.java:132)\n\tat py4j.commands.CallCommand.execute(CallCommand.java:79)\n\tat py4j.GatewayConnection.run(GatewayConnection.java:238)\n\tat java.base/java.lang.Thread.run(Thread.java:834)\n",
     "output_type": "error",
     "traceback": [
      "\u001b[0;31m---------------------------------------------------------------------------\u001b[0m",
      "\u001b[0;31mPy4JJavaError\u001b[0m                             Traceback (most recent call last)",
      "\u001b[0;32m<ipython-input-15-ae1f6f6b3368>\u001b[0m in \u001b[0;36m<module>\u001b[0;34m\u001b[0m\n\u001b[0;32m----> 1\u001b[0;31m \u001b[0mv_dia_group_pd\u001b[0m \u001b[0;34m=\u001b[0m \u001b[0mvendas_dia_group\u001b[0m\u001b[0;34m.\u001b[0m\u001b[0morderBy\u001b[0m\u001b[0;34m(\u001b[0m\u001b[0;34m\"Date\"\u001b[0m\u001b[0;34m)\u001b[0m\u001b[0;34m.\u001b[0m\u001b[0mtoPandas\u001b[0m\u001b[0;34m(\u001b[0m\u001b[0;34m)\u001b[0m\u001b[0;34m\u001b[0m\u001b[0;34m\u001b[0m\u001b[0m\n\u001b[0m",
      "\u001b[0;32m/opt/spark/python/pyspark/sql/dataframe.py\u001b[0m in \u001b[0;36mtoPandas\u001b[0;34m(self)\u001b[0m\n\u001b[1;32m   2140\u001b[0m \u001b[0;34m\u001b[0m\u001b[0m\n\u001b[1;32m   2141\u001b[0m         \u001b[0;31m# Below is toPandas without Arrow optimization.\u001b[0m\u001b[0;34m\u001b[0m\u001b[0;34m\u001b[0m\u001b[0;34m\u001b[0m\u001b[0m\n\u001b[0;32m-> 2142\u001b[0;31m         \u001b[0mpdf\u001b[0m \u001b[0;34m=\u001b[0m \u001b[0mpd\u001b[0m\u001b[0;34m.\u001b[0m\u001b[0mDataFrame\u001b[0m\u001b[0;34m.\u001b[0m\u001b[0mfrom_records\u001b[0m\u001b[0;34m(\u001b[0m\u001b[0mself\u001b[0m\u001b[0;34m.\u001b[0m\u001b[0mcollect\u001b[0m\u001b[0;34m(\u001b[0m\u001b[0;34m)\u001b[0m\u001b[0;34m,\u001b[0m \u001b[0mcolumns\u001b[0m\u001b[0;34m=\u001b[0m\u001b[0mself\u001b[0m\u001b[0;34m.\u001b[0m\u001b[0mcolumns\u001b[0m\u001b[0;34m)\u001b[0m\u001b[0;34m\u001b[0m\u001b[0;34m\u001b[0m\u001b[0m\n\u001b[0m\u001b[1;32m   2143\u001b[0m \u001b[0;34m\u001b[0m\u001b[0m\n\u001b[1;32m   2144\u001b[0m         \u001b[0mdtype\u001b[0m \u001b[0;34m=\u001b[0m \u001b[0;34m{\u001b[0m\u001b[0;34m}\u001b[0m\u001b[0;34m\u001b[0m\u001b[0;34m\u001b[0m\u001b[0m\n",
      "\u001b[0;32m/opt/spark/python/pyspark/sql/dataframe.py\u001b[0m in \u001b[0;36mcollect\u001b[0;34m(self)\u001b[0m\n\u001b[1;32m    531\u001b[0m         \"\"\"\n\u001b[1;32m    532\u001b[0m         \u001b[0;32mwith\u001b[0m \u001b[0mSCCallSiteSync\u001b[0m\u001b[0;34m(\u001b[0m\u001b[0mself\u001b[0m\u001b[0;34m.\u001b[0m\u001b[0m_sc\u001b[0m\u001b[0;34m)\u001b[0m \u001b[0;32mas\u001b[0m \u001b[0mcss\u001b[0m\u001b[0;34m:\u001b[0m\u001b[0;34m\u001b[0m\u001b[0;34m\u001b[0m\u001b[0m\n\u001b[0;32m--> 533\u001b[0;31m             \u001b[0msock_info\u001b[0m \u001b[0;34m=\u001b[0m \u001b[0mself\u001b[0m\u001b[0;34m.\u001b[0m\u001b[0m_jdf\u001b[0m\u001b[0;34m.\u001b[0m\u001b[0mcollectToPython\u001b[0m\u001b[0;34m(\u001b[0m\u001b[0;34m)\u001b[0m\u001b[0;34m\u001b[0m\u001b[0;34m\u001b[0m\u001b[0m\n\u001b[0m\u001b[1;32m    534\u001b[0m         \u001b[0;32mreturn\u001b[0m \u001b[0mlist\u001b[0m\u001b[0;34m(\u001b[0m\u001b[0m_load_from_socket\u001b[0m\u001b[0;34m(\u001b[0m\u001b[0msock_info\u001b[0m\u001b[0;34m,\u001b[0m \u001b[0mBatchedSerializer\u001b[0m\u001b[0;34m(\u001b[0m\u001b[0mPickleSerializer\u001b[0m\u001b[0;34m(\u001b[0m\u001b[0;34m)\u001b[0m\u001b[0;34m)\u001b[0m\u001b[0;34m)\u001b[0m\u001b[0;34m)\u001b[0m\u001b[0;34m\u001b[0m\u001b[0;34m\u001b[0m\u001b[0m\n\u001b[1;32m    535\u001b[0m \u001b[0;34m\u001b[0m\u001b[0m\n",
      "\u001b[0;32m/opt/spark/python/lib/py4j-0.10.7-src.zip/py4j/java_gateway.py\u001b[0m in \u001b[0;36m__call__\u001b[0;34m(self, *args)\u001b[0m\n\u001b[1;32m   1255\u001b[0m         \u001b[0manswer\u001b[0m \u001b[0;34m=\u001b[0m \u001b[0mself\u001b[0m\u001b[0;34m.\u001b[0m\u001b[0mgateway_client\u001b[0m\u001b[0;34m.\u001b[0m\u001b[0msend_command\u001b[0m\u001b[0;34m(\u001b[0m\u001b[0mcommand\u001b[0m\u001b[0;34m)\u001b[0m\u001b[0;34m\u001b[0m\u001b[0;34m\u001b[0m\u001b[0m\n\u001b[1;32m   1256\u001b[0m         return_value = get_return_value(\n\u001b[0;32m-> 1257\u001b[0;31m             answer, self.gateway_client, self.target_id, self.name)\n\u001b[0m\u001b[1;32m   1258\u001b[0m \u001b[0;34m\u001b[0m\u001b[0m\n\u001b[1;32m   1259\u001b[0m         \u001b[0;32mfor\u001b[0m \u001b[0mtemp_arg\u001b[0m \u001b[0;32min\u001b[0m \u001b[0mtemp_args\u001b[0m\u001b[0;34m:\u001b[0m\u001b[0;34m\u001b[0m\u001b[0;34m\u001b[0m\u001b[0m\n",
      "\u001b[0;32m/opt/spark/python/pyspark/sql/utils.py\u001b[0m in \u001b[0;36mdeco\u001b[0;34m(*a, **kw)\u001b[0m\n\u001b[1;32m     61\u001b[0m     \u001b[0;32mdef\u001b[0m \u001b[0mdeco\u001b[0m\u001b[0;34m(\u001b[0m\u001b[0;34m*\u001b[0m\u001b[0ma\u001b[0m\u001b[0;34m,\u001b[0m \u001b[0;34m**\u001b[0m\u001b[0mkw\u001b[0m\u001b[0;34m)\u001b[0m\u001b[0;34m:\u001b[0m\u001b[0;34m\u001b[0m\u001b[0;34m\u001b[0m\u001b[0m\n\u001b[1;32m     62\u001b[0m         \u001b[0;32mtry\u001b[0m\u001b[0;34m:\u001b[0m\u001b[0;34m\u001b[0m\u001b[0;34m\u001b[0m\u001b[0m\n\u001b[0;32m---> 63\u001b[0;31m             \u001b[0;32mreturn\u001b[0m \u001b[0mf\u001b[0m\u001b[0;34m(\u001b[0m\u001b[0;34m*\u001b[0m\u001b[0ma\u001b[0m\u001b[0;34m,\u001b[0m \u001b[0;34m**\u001b[0m\u001b[0mkw\u001b[0m\u001b[0;34m)\u001b[0m\u001b[0;34m\u001b[0m\u001b[0;34m\u001b[0m\u001b[0m\n\u001b[0m\u001b[1;32m     64\u001b[0m         \u001b[0;32mexcept\u001b[0m \u001b[0mpy4j\u001b[0m\u001b[0;34m.\u001b[0m\u001b[0mprotocol\u001b[0m\u001b[0;34m.\u001b[0m\u001b[0mPy4JJavaError\u001b[0m \u001b[0;32mas\u001b[0m \u001b[0me\u001b[0m\u001b[0;34m:\u001b[0m\u001b[0;34m\u001b[0m\u001b[0;34m\u001b[0m\u001b[0m\n\u001b[1;32m     65\u001b[0m             \u001b[0ms\u001b[0m \u001b[0;34m=\u001b[0m \u001b[0me\u001b[0m\u001b[0;34m.\u001b[0m\u001b[0mjava_exception\u001b[0m\u001b[0;34m.\u001b[0m\u001b[0mtoString\u001b[0m\u001b[0;34m(\u001b[0m\u001b[0;34m)\u001b[0m\u001b[0;34m\u001b[0m\u001b[0;34m\u001b[0m\u001b[0m\n",
      "\u001b[0;32m/opt/spark/python/lib/py4j-0.10.7-src.zip/py4j/protocol.py\u001b[0m in \u001b[0;36mget_return_value\u001b[0;34m(answer, gateway_client, target_id, name)\u001b[0m\n\u001b[1;32m    326\u001b[0m                 raise Py4JJavaError(\n\u001b[1;32m    327\u001b[0m                     \u001b[0;34m\"An error occurred while calling {0}{1}{2}.\\n\"\u001b[0m\u001b[0;34m.\u001b[0m\u001b[0;34m\u001b[0m\u001b[0;34m\u001b[0m\u001b[0m\n\u001b[0;32m--> 328\u001b[0;31m                     format(target_id, \".\", name), value)\n\u001b[0m\u001b[1;32m    329\u001b[0m             \u001b[0;32melse\u001b[0m\u001b[0;34m:\u001b[0m\u001b[0;34m\u001b[0m\u001b[0;34m\u001b[0m\u001b[0m\n\u001b[1;32m    330\u001b[0m                 raise Py4JError(\n",
      "\u001b[0;31mPy4JJavaError\u001b[0m: An error occurred while calling o169.collectToPython.\n: org.apache.spark.SparkException: Job aborted due to stage failure: Task 13 in stage 7.0 failed 1 times, most recent failure: Lost task 13.0 in stage 7.0 (TID 433, localhost, executor driver): ExecutorLostFailure (executor driver exited caused by one of the running tasks) Reason: Executor heartbeat timed out after 451499 ms\nDriver stacktrace:\n\tat org.apache.spark.scheduler.DAGScheduler.failJobAndIndependentStages(DAGScheduler.scala:1889)\n\tat org.apache.spark.scheduler.DAGScheduler.$anonfun$abortStage$2(DAGScheduler.scala:1877)\n\tat org.apache.spark.scheduler.DAGScheduler.$anonfun$abortStage$2$adapted(DAGScheduler.scala:1876)\n\tat scala.collection.mutable.ResizableArray.foreach(ResizableArray.scala:62)\n\tat scala.collection.mutable.ResizableArray.foreach$(ResizableArray.scala:55)\n\tat scala.collection.mutable.ArrayBuffer.foreach(ArrayBuffer.scala:49)\n\tat org.apache.spark.scheduler.DAGScheduler.abortStage(DAGScheduler.scala:1876)\n\tat org.apache.spark.scheduler.DAGScheduler.$anonfun$handleTaskSetFailed$1(DAGScheduler.scala:926)\n\tat org.apache.spark.scheduler.DAGScheduler.$anonfun$handleTaskSetFailed$1$adapted(DAGScheduler.scala:926)\n\tat scala.Option.foreach(Option.scala:274)\n\tat org.apache.spark.scheduler.DAGScheduler.handleTaskSetFailed(DAGScheduler.scala:926)\n\tat org.apache.spark.scheduler.DAGSchedulerEventProcessLoop.doOnReceive(DAGScheduler.scala:2110)\n\tat org.apache.spark.scheduler.DAGSchedulerEventProcessLoop.onReceive(DAGScheduler.scala:2059)\n\tat org.apache.spark.scheduler.DAGSchedulerEventProcessLoop.onReceive(DAGScheduler.scala:2048)\n\tat org.apache.spark.util.EventLoop$$anon$1.run(EventLoop.scala:49)\n\tat org.apache.spark.scheduler.DAGScheduler.runJob(DAGScheduler.scala:737)\n\tat org.apache.spark.SparkContext.runJob(SparkContext.scala:2061)\n\tat org.apache.spark.SparkContext.runJob(SparkContext.scala:2082)\n\tat org.apache.spark.SparkContext.runJob(SparkContext.scala:2101)\n\tat org.apache.spark.SparkContext.runJob(SparkContext.scala:2126)\n\tat org.apache.spark.rdd.RDD.$anonfun$collect$1(RDD.scala:945)\n\tat org.apache.spark.rdd.RDDOperationScope$.withScope(RDDOperationScope.scala:151)\n\tat org.apache.spark.rdd.RDDOperationScope$.withScope(RDDOperationScope.scala:112)\n\tat org.apache.spark.rdd.RDD.withScope(RDD.scala:363)\n\tat org.apache.spark.rdd.RDD.collect(RDD.scala:944)\n\tat org.apache.spark.sql.execution.SparkPlan.executeCollect(SparkPlan.scala:299)\n\tat org.apache.spark.sql.Dataset.$anonfun$collectToPython$1(Dataset.scala:3257)\n\tat org.apache.spark.sql.Dataset.$anonfun$withAction$2(Dataset.scala:3364)\n\tat org.apache.spark.sql.execution.SQLExecution$.$anonfun$withNewExecutionId$1(SQLExecution.scala:78)\n\tat org.apache.spark.sql.execution.SQLExecution$.withSQLConfPropagated(SQLExecution.scala:125)\n\tat org.apache.spark.sql.execution.SQLExecution$.withNewExecutionId(SQLExecution.scala:73)\n\tat org.apache.spark.sql.Dataset.withAction(Dataset.scala:3364)\n\tat org.apache.spark.sql.Dataset.collectToPython(Dataset.scala:3254)\n\tat java.base/jdk.internal.reflect.NativeMethodAccessorImpl.invoke0(Native Method)\n\tat java.base/jdk.internal.reflect.NativeMethodAccessorImpl.invoke(NativeMethodAccessorImpl.java:62)\n\tat java.base/jdk.internal.reflect.DelegatingMethodAccessorImpl.invoke(DelegatingMethodAccessorImpl.java:43)\n\tat java.base/java.lang.reflect.Method.invoke(Method.java:566)\n\tat py4j.reflection.MethodInvoker.invoke(MethodInvoker.java:244)\n\tat py4j.reflection.ReflectionEngine.invoke(ReflectionEngine.java:357)\n\tat py4j.Gateway.invoke(Gateway.java:282)\n\tat py4j.commands.AbstractCommand.invokeMethod(AbstractCommand.java:132)\n\tat py4j.commands.CallCommand.execute(CallCommand.java:79)\n\tat py4j.GatewayConnection.run(GatewayConnection.java:238)\n\tat java.base/java.lang.Thread.run(Thread.java:834)\n"
     ]
    }
   ],
   "source": [
    "v_dia_group_pd = vendas_dia_group.orderBy(\"Date\").toPandas()"
   ]
  },
  {
   "cell_type": "code",
   "execution_count": null,
   "metadata": {},
   "outputs": [],
   "source": []
  },
  {
   "cell_type": "code",
   "execution_count": null,
   "metadata": {},
   "outputs": [],
   "source": [
    "px.line(v_dia_group_pd, x=\"Date\", y=[\"meio\", \"sum(Volume)\"])"
   ]
  },
  {
   "cell_type": "code",
   "execution_count": null,
   "metadata": {},
   "outputs": [],
   "source": []
  },
  {
   "cell_type": "code",
   "execution_count": null,
   "metadata": {},
   "outputs": [],
   "source": []
  },
  {
   "cell_type": "code",
   "execution_count": null,
   "metadata": {},
   "outputs": [],
   "source": []
  },
  {
   "cell_type": "code",
   "execution_count": null,
   "metadata": {},
   "outputs": [],
   "source": []
  },
  {
   "cell_type": "code",
   "execution_count": null,
   "metadata": {},
   "outputs": [],
   "source": []
  },
  {
   "cell_type": "code",
   "execution_count": null,
   "metadata": {},
   "outputs": [],
   "source": []
  },
  {
   "cell_type": "code",
   "execution_count": null,
   "metadata": {},
   "outputs": [],
   "source": []
  }
 ],
 "metadata": {
  "kernelspec": {
   "display_name": "Python 3",
   "language": "python",
   "name": "python3"
  },
  "language_info": {
   "codemirror_mode": {
    "name": "ipython",
    "version": 3
   },
   "file_extension": ".py",
   "mimetype": "text/x-python",
   "name": "python",
   "nbconvert_exporter": "python",
   "pygments_lexer": "ipython3",
   "version": "3.7.6"
  }
 },
 "nbformat": 4,
 "nbformat_minor": 4
}
